<sdf version='1.7'>
  <world name='lab_world'>
    <physics name='1ms' type='ignored'>
      <max_step_size>0.001</max_step_size>
      <real_time_factor>1</real_time_factor>
      <real_time_update_rate>1000</real_time_update_rate>
    </physics>
    <plugin name='ignition::gazebo::systems::Physics' filename='ignition-gazebo-physics-system'/>
    <plugin name='ignition::gazebo::systems::UserCommands' filename='ignition-gazebo-user-commands-system'/>
    <plugin name='ignition::gazebo::systems::SceneBroadcaster' filename='ignition-gazebo-scene-broadcaster-system'/>
    <gui fullscreen='0'>
      <plugin name='3D View' filename='GzScene3D'>
        <ignition-gui>
          <title>3D View</title>
          <property type='bool' key='showTitleBar'>0</property>
          <property type='string' key='state'>docked</property>
        </ignition-gui>
        <engine>ogre2</engine>
        <scene>scene</scene>
        <ambient_light>0.4 0.4 0.4</ambient_light>
        <background_color>0.8 0.8 0.8</background_color>
        <camera_pose>2 2 2 0 0.5 -2.5</camera_pose>
      </plugin>
      <plugin name='World control' filename='WorldControl'>
        <ignition-gui>
          <title>World control</title>
          <property type='bool' key='showTitleBar'>0</property>
          <property type='bool' key='resizable'>0</property>
          <property type='double' key='height'>72</property>
          <property type='double' key='width'>121</property>
          <property type='double' key='z'>1</property>
          <property type='string' key='state'>floating</property>
          <anchors target='3D View'>
            <line own='left' target='left'/>
            <line own='bottom' target='bottom'/>
          </anchors>
        </ignition-gui>
        <play_pause>1</play_pause>
        <step>1</step>
        <start_paused>1</start_paused>
      </plugin>
      <plugin name='World stats' filename='WorldStats'>
        <ignition-gui>
          <title>World stats</title>
          <property type='bool' key='showTitleBar'>0</property>
          <property type='bool' key='resizable'>0</property>
          <property type='double' key='height'>110</property>
          <property type='double' key='width'>290</property>
          <property type='double' key='z'>1</property>
          <property type='string' key='state'>floating</property>
          <anchors target='3D View'>
            <line own='right' target='right'/>
            <line own='bottom' target='bottom'/>
          </anchors>
        </ignition-gui>
        <sim_time>1</sim_time>
        <real_time>1</real_time>
        <real_time_factor>1</real_time_factor>
        <iterations>1</iterations>
      </plugin>
      <plugin name='JointPositionController' filename='JointPositionController'>
        <ignition-gui>
          <property type='double' key='height'>600</property>
          <property type='double' key='width'>400</property>
          <property type='string' key='state'>floating</property>
          <anchors target='3D View'>
            <line own='right' target='right'/>
            <line own='top' target='top'/>
          </anchors>
        </ignition-gui>
        <model_name>panda</model_name>
      </plugin>
    </gui>
    <light name='sun' type='directional'>
      <cast_shadows>1</cast_shadows>
      <pose>0 0 10 0 -0 0</pose>
      <diffuse>0.8 0.8 0.8 1</diffuse>
      <specular>0.2 0.2 0.2 1</specular>
      <attenuation>
        <range>1000</range>
        <constant>0.9</constant>
        <linear>0.01</linear>
        <quadratic>0.001</quadratic>
      </attenuation>
      <direction>-0.5 0.1 -0.9</direction>
      <spot>
        <inner_angle>0</inner_angle>
        <outer_angle>0</outer_angle>
        <falloff>0</falloff>
      </spot>
    </light>
    <gravity>0 0 -9.8</gravity>
    <magnetic_field>6e-06 2.3e-05 -4.2e-05</magnetic_field>
    <atmosphere type='adiabatic'/>
    <scene>
      <ambient>0.4 0.4 0.4 1</ambient>
      <background>0.7 0.7 0.7 1</background>
      <shadows>1</shadows>
    </scene>
    <model name='ground_plane'>
      <static>1</static>
      <link name='link'>
        <collision name='collision'>
          <geometry>
            <plane>
              <normal>0 0 1</normal>
              <size>100 100</size>
            </plane>
          </geometry>
          <surface>
            <friction>
              <ode/>
            </friction>
            <bounce/>
            <contact/>
          </surface>
        </collision>
        <visual name='visual'>
          <geometry>
            <plane>
              <normal>0 0 1</normal>
              <size>100 100</size>
            </plane>
          </geometry>
          <material>
            <ambient>0.8 0.8 0.8 1</ambient>
            <diffuse>0.8 0.8 0.8 1</diffuse>
            <specular>0.8 0.8 0.8 1</specular>
          </material>
        </visual>
      </link>
      <pose>0 0 0 0 -0 0</pose>
    </model>
    <include>
      <uri>
      file://home/truan/Object-Detection/simulation/catkin_ws/src/gazebo_sim/models/RAH_lab
      </uri>
      <name>RAH_lab</name>
      <pose>1.41433 -1.46412 0 0 -0 0</pose>
    </include>
    <model name='panda'>
      <joint name='panda_joint_world' type='fixed'>
        <parent>world</parent>
        <child>panda_link0</child>
      </joint>
      <link name='panda_link0'>
        <visual name='panda_link0_visual'>
          <geometry>
            <mesh>
              <uri>file:///home/truan/Object-Detection/simulation/catkin_ws/src/gazebo_sim/models/Panda arm - Fortress merge include demo/meshes/visual/link0.dae</uri>
            </mesh>
          </geometry>
          <material>
            <diffuse>1 1 1 1</diffuse>
            <specular>1 1 1 1</specular>
          </material>
        </visual>
        <collision name='panda_link0_collision'>
          <geometry>
            <mesh>
              <uri>file:///home/truan/Object-Detection/simulation/catkin_ws/src/gazebo_sim/models/Panda arm - Fortress merge include demo/meshes/collision/link0.stl</uri>
            </mesh>
          </geometry>
          <surface>
            <friction>
              <ode>
                <mu>1.05</mu>
                <mu2>1.05</mu2>
              </ode>
            </friction>
          </surface>
        </collision>
        <inertial>
          <pose>-0.025566 -2.9e-05 0.057332 0 -0 0</pose>
          <mass>2.81427</mass>
          <inertia>
            <ixx>0.00753906</ixx>
            <iyy>0.010508</iyy>
            <izz>0.00986493</izz>
            <ixy>-1.50531e-05</ixy>
            <ixz>-0.00121443</ixz>
            <iyz>1.04348e-05</iyz>
          </inertia>
        </inertial>
      </link>
      <link name='panda_link1'>
        <pose relative_to='panda_joint1'>0 0 0 0 -0 0</pose>
        <visual name='panda_link1_visual'>
          <geometry>
            <mesh>
              <uri>file:///home/truan/Object-Detection/simulation/catkin_ws/src/gazebo_sim/models/Panda arm - Fortress merge include demo/meshes/visual/link1.dae</uri>
            </mesh>
          </geometry>
          <material>
            <diffuse>1 1 1 1</diffuse>
            <specular>1 1 1 1</specular>
          </material>
        </visual>
        <collision name='panda_link1_collision'>
          <geometry>
            <mesh>
              <uri>file:///home/truan/Object-Detection/simulation/catkin_ws/src/gazebo_sim/models/Panda arm - Fortress merge include demo/meshes/collision/link1.stl</uri>
            </mesh>
          </geometry>
          <surface>
            <friction>
              <ode>
                <mu>1.05</mu>
                <mu2>1.05</mu2>
              </ode>
            </friction>
          </surface>
        </collision>
        <inertial>
          <pose>-0 -0.032496 -0.067582 0 -0 0</pose>
          <mass>2.64332</mass>
          <inertia>
            <ixx>0.0174051</ixx>
            <iyy>0.0153521</iyy>
            <izz>0.00598789</izz>
            <ixy>-8.68799e-09</ixy>
            <ixz>-1.62778e-08</ixz>
            <iyz>0.00451086</iyz>
          </inertia>
        </inertial>
      </link>
      <link name='panda_link2'>
        <pose relative_to='panda_joint2'>0 0 0 0 -0 0</pose>
        <visual name='panda_link2_visual'>
          <geometry>
            <mesh>
              <uri>file:///home/truan/Object-Detection/simulation/catkin_ws/src/gazebo_sim/models/Panda arm - Fortress merge include demo/meshes/visual/link2.dae</uri>
            </mesh>
          </geometry>
          <material>
            <diffuse>1 1 1 1</diffuse>
            <specular>1 1 1 1</specular>
          </material>
        </visual>
        <collision name='panda_link2_collision'>
          <geometry>
            <mesh>
              <uri>file:///home/truan/Object-Detection/simulation/catkin_ws/src/gazebo_sim/models/Panda arm - Fortress merge include demo/meshes/collision/link2.stl</uri>
            </mesh>
          </geometry>
          <surface>
            <friction>
              <ode>
                <mu>1.05</mu>
                <mu2>1.05</mu2>
              </ode>
            </friction>
          </surface>
        </collision>
        <inertial>
          <pose>0 -0.06861 0.032229 0 -0 0</pose>
          <mass>2.66528</mass>
          <inertia>
            <ixx>0.0177869</ixx>
            <iyy>0.00604413</iyy>
            <izz>0.015711</izz>
            <ixy>8.70636e-08</ixy>
            <ixz>3.75207e-08</ixz>
            <iyz>-0.00459949</iyz>
          </inertia>
        </inertial>
      </link>
      <link name='panda_link3'>
        <pose relative_to='panda_joint3'>0 0 0 0 -0 0</pose>
        <visual name='panda_link3_visual'>
          <geometry>
            <mesh>
              <uri>file:///home/truan/Object-Detection/simulation/catkin_ws/src/gazebo_sim/models/Panda arm - Fortress merge include demo/meshes/visual/link3.dae</uri>
            </mesh>
          </geometry>
          <material>
            <diffuse>1 1 1 1</diffuse>
            <specular>1 1 1 1</specular>
          </material>
        </visual>
        <collision name='panda_link3_collision'>
          <geometry>
            <mesh>
              <uri>file:///home/truan/Object-Detection/simulation/catkin_ws/src/gazebo_sim/models/Panda arm - Fortress merge include demo/meshes/collision/link3.stl</uri>
            </mesh>
          </geometry>
          <surface>
            <friction>
              <ode>
                <mu>1.05</mu>
                <mu2>1.05</mu2>
              </ode>
            </friction>
          </surface>
        </collision>
        <inertial>
          <pose>0.046989 0.031637 -0.031704 0 -0 0</pose>
          <mass>2.32937</mass>
          <inertia>
            <ixx>0.00754968</ixx>
            <iyy>0.00968068</iyy>
            <izz>0.00794456</izz>
            <ixy>-0.00243205</ixy>
            <ixz>-0.00325082</ixz>
            <iyz>-0.00213163</iyz>
          </inertia>
        </inertial>
      </link>
      <link name='panda_link4'>
        <pose relative_to='panda_joint4'>0 0 0 0 -0 0</pose>
        <visual name='panda_link4_visual'>
          <geometry>
            <mesh>
              <uri>file:///home/truan/Object-Detection/simulation/catkin_ws/src/gazebo_sim/models/Panda arm - Fortress merge include demo/meshes/visual/link4.dae</uri>
            </mesh>
          </geometry>
          <material>
            <diffuse>1 1 1 1</diffuse>
            <specular>1 1 1 1</specular>
          </material>
        </visual>
        <collision name='panda_link4_collision'>
          <geometry>
            <mesh>
              <uri>file:///home/truan/Object-Detection/simulation/catkin_ws/src/gazebo_sim/models/Panda arm - Fortress merge include demo/meshes/collision/link4.stl</uri>
            </mesh>
          </geometry>
          <surface>
            <friction>
              <ode>
                <mu>1.05</mu>
                <mu2>1.05</mu2>
              </ode>
            </friction>
          </surface>
        </collision>
        <inertial>
          <pose>-0.036051 0.033707 0.031902 0 -0 0</pose>
          <mass>2.31048</mass>
          <inertia>
            <ixx>0.00776457</ixx>
            <iyy>0.00801578</iyy>
            <izz>0.00995588</izz>
            <ixy>0.00337148</ixy>
            <ixz>-0.00234362</ixz>
            <iyz>0.00229175</iyz>
          </inertia>
        </inertial>
      </link>
      <link name='panda_link5'>
        <pose relative_to='panda_joint5'>0 0 0 0 -0 0</pose>
        <visual name='panda_link5_visual'>
          <geometry>
            <mesh>
              <uri>file:///home/truan/Object-Detection/simulation/catkin_ws/src/gazebo_sim/models/Panda arm - Fortress merge include demo/meshes/visual/link5.dae</uri>
            </mesh>
          </geometry>
          <material>
            <diffuse>1 1 1 1</diffuse>
            <specular>1 1 1 1</specular>
          </material>
        </visual>
        <collision name='panda_link5_collision'>
          <geometry>
            <mesh>
              <uri>file:///home/truan/Object-Detection/simulation/catkin_ws/src/gazebo_sim/models/Panda arm - Fortress merge include demo/meshes/collision/link5.stl</uri>
            </mesh>
          </geometry>
          <surface>
            <friction>
              <ode>
                <mu>1.05</mu>
                <mu2>1.05</mu2>
              </ode>
            </friction>
          </surface>
        </collision>
        <inertial>
          <pose>-6e-06 0.061043 -0.104176 0 -0 0</pose>
          <mass>2.62264</mass>
          <inertia>
            <ixx>0.0290705</ixx>
            <iyy>0.0276385</iyy>
            <izz>0.00425111</izz>
            <ixy>6.20874e-07</ixy>
            <ixz>-1.00592e-05</ixz>
            <iyz>-0.00742431</iyz>
          </inertia>
        </inertial>
      </link>
      <link name='panda_link6'>
        <pose relative_to='panda_joint6'>0 0 0 0 -0 0</pose>
        <visual name='panda_link6_visual'>
          <geometry>
            <mesh>
              <uri>file:///home/truan/Object-Detection/simulation/catkin_ws/src/gazebo_sim/models/Panda arm - Fortress merge include demo/meshes/visual/link6.dae</uri>
            </mesh>
          </geometry>
          <material>
            <diffuse>1 1 1 1</diffuse>
            <specular>1 1 1 1</specular>
          </material>
        </visual>
        <collision name='panda_link6_collision'>
          <geometry>
            <mesh>
              <uri>file:///home/truan/Object-Detection/simulation/catkin_ws/src/gazebo_sim/models/Panda arm - Fortress merge include demo/meshes/collision/link6.stl</uri>
            </mesh>
          </geometry>
          <surface>
            <friction>
              <ode>
                <mu>1.05</mu>
                <mu2>1.05</mu2>
              </ode>
            </friction>
          </surface>
        </collision>
        <inertial>
          <pose>0.051051 0.009108 0.010634 0 -0 0</pose>
          <mass>1.50258</mass>
          <inertia>
            <ixx>0.00294056</ixx>
            <iyy>0.00392105</iyy>
            <izz>0.00541156</izz>
            <ixy>-0.000423911</ixy>
            <ixz>0.000610008</ixz>
            <iyz>0.000126475</iyz>
          </inertia>
        </inertial>
      </link>
      <link name='panda_link7'>
        <pose relative_to='panda_joint7'>0 0 0 0 -0 0</pose>
        <visual name='panda_link7_visual'>
          <geometry>
            <mesh>
              <uri>file:///home/truan/Object-Detection/simulation/catkin_ws/src/gazebo_sim/models/Panda arm - Fortress merge include demo/meshes/visual/link7.dae</uri>
            </mesh>
          </geometry>
          <material>
            <diffuse>1 1 1 1</diffuse>
            <specular>1 1 1 1</specular>
          </material>
        </visual>
        <collision name='panda_link7_collision'>
          <geometry>
            <mesh>
              <uri>file:///home/truan/Object-Detection/simulation/catkin_ws/src/gazebo_sim/models/Panda arm - Fortress merge include demo/meshes/collision/link7.stl</uri>
            </mesh>
          </geometry>
          <surface>
            <friction>
              <ode>
                <mu>1.05</mu>
                <mu2>1.05</mu2>
              </ode>
            </friction>
          </surface>
        </collision>
        <inertial>
          <pose>0.01097 0.010797 0.065041 0 -0 0</pose>
          <mass>0.523767</mass>
          <inertia>
            <ixx>0.000862147</ixx>
            <iyy>0.00086131</iyy>
            <izz>0.000696114</izz>
            <ixy>-0.000118711</ixy>
            <ixz>3.8666e-05</ixz>
            <iyz>-9.05784e-05</iyz>
          </inertia>
        </inertial>
      </link>
      <joint name='panda_joint1' type='revolute'>
        <pose relative_to='panda_link0'>0 0 0.333 0 -0 0</pose>
        <parent>panda_link0</parent>
        <child>panda_link1</child>
        <axis>
          <xyz>0 0 1</xyz>
          <limit>
            <effort>87</effort>
            <lower>-2.89725</lower>
            <upper>2.89725</upper>
            <velocity>2.61799</velocity>
          </limit>
          <dynamics>
            <spring_reference>0</spring_reference>
            <spring_stiffness>0</spring_stiffness>
            <damping>21.75</damping>
            <friction>3.48</friction>
          </dynamics>
        </axis>
      </joint>
      <joint name='panda_joint2' type='revolute'>
        <pose relative_to='panda_link1'>0 0 0 -1.5708 0 0</pose>
        <parent>panda_link1</parent>
        <child>panda_link2</child>
        <axis>
          <xyz>0 0 1</xyz>
          <limit>
            <effort>87</effort>
            <lower>-1.76278</lower>
            <upper>1.76278</upper>
            <velocity>2.61799</velocity>
          </limit>
          <dynamics>
            <spring_reference>0</spring_reference>
            <spring_stiffness>0</spring_stiffness>
            <damping>21.75</damping>
            <friction>3.48</friction>
          </dynamics>
        </axis>
      </joint>
      <joint name='panda_joint3' type='revolute'>
        <pose relative_to='panda_link2'>0 -0.316 0 1.5708 -0 0</pose>
        <parent>panda_link2</parent>
        <child>panda_link3</child>
        <axis>
          <xyz>0 0 1</xyz>
          <limit>
            <effort>87</effort>
            <lower>-2.89725</lower>
            <upper>2.89725</upper>
            <velocity>2.61799</velocity>
          </limit>
          <dynamics>
            <spring_reference>0</spring_reference>
            <spring_stiffness>0</spring_stiffness>
            <damping>21.75</damping>
            <friction>3.48</friction>
          </dynamics>
        </axis>
      </joint>
      <joint name='panda_joint4' type='revolute'>
        <pose relative_to='panda_link3'>0.0825 0 0 1.5708 -0 0</pose>
        <parent>panda_link3</parent>
        <child>panda_link4</child>
        <axis>
          <xyz>0 0 1</xyz>
          <limit>
            <effort>87</effort>
            <lower>-3.07178</lower>
            <upper>-0.0698132</upper>
            <velocity>2.61799</velocity>
          </limit>
          <dynamics>
            <spring_reference>0</spring_reference>
            <spring_stiffness>0</spring_stiffness>
            <damping>21.75</damping>
            <friction>3.48</friction>
          </dynamics>
        </axis>
      </joint>
      <joint name='panda_joint5' type='revolute'>
        <pose relative_to='panda_link4'>-0.0825 0.384 0 -1.5708 0 0</pose>
        <parent>panda_link4</parent>
        <child>panda_link5</child>
        <axis>
          <xyz>0 0 1</xyz>
          <limit>
            <effort>12</effort>
            <lower>-2.89725</lower>
            <upper>2.89725</upper>
            <velocity>3.14159</velocity>
          </limit>
          <dynamics>
            <spring_reference>0</spring_reference>
            <spring_stiffness>0</spring_stiffness>
            <damping>3</damping>
            <friction>0.48</friction>
          </dynamics>
        </axis>
      </joint>
      <joint name='panda_joint6' type='revolute'>
        <pose relative_to='panda_link5'>0 0 0 1.5708 -0 0</pose>
        <parent>panda_link5</parent>
        <child>panda_link6</child>
        <axis>
          <xyz>0 0 1</xyz>
          <limit>
            <effort>12</effort>
            <lower>-0.0174533</lower>
            <upper>3.75246</upper>
            <velocity>3.14159</velocity>
          </limit>
          <dynamics>
            <spring_reference>0</spring_reference>
            <spring_stiffness>0</spring_stiffness>
            <damping>3</damping>
            <friction>0.48</friction>
          </dynamics>
        </axis>
      </joint>
      <joint name='panda_joint7' type='revolute'>
        <pose relative_to='panda_link6'>0.088 0 0 1.5708 -0 0</pose>
        <parent>panda_link6</parent>
        <child>panda_link7</child>
        <axis>
          <xyz>0 0 1</xyz>
          <limit>
            <effort>12</effort>
            <lower>-2.89725</lower>
            <upper>2.89725</upper>
            <velocity>3.14159</velocity>
          </limit>
          <dynamics>
            <spring_reference>0</spring_reference>
            <spring_stiffness>0</spring_stiffness>
            <damping>3</damping>
            <friction>0.48</friction>
          </dynamics>
        </axis>
      </joint>
      <joint name='panda_hand_joint' type='fixed'>
        <pose relative_to='panda_link7'>0 0 0.107 0 0 -0.785398</pose>
        <parent>panda_link7</parent>
        <child>panda_hand</child>
      </joint>
      <link name='panda_hand'>
        <pose relative_to='panda_hand_joint'>0 0 0 0 -0 0</pose>
        <visual name='panda_hand_visual'>
          <pose>0 0 0 0 -0 0</pose>
          <geometry>
            <mesh>
              <uri>file:///home/truan/Object-Detection/simulation/catkin_ws/src/gazebo_sim/models/Panda arm - Fortress merge include demo/meshes/visual/hand.dae</uri>
            </mesh>
          </geometry>
          <material>
            <diffuse>1 1 1 1</diffuse>
            <specular>1 1 1 1</specular>
          </material>
        </visual>
        <collision name='panda_hand_collision'>
          <pose>0 0 0 0 -0 0</pose>
          <geometry>
            <mesh>
              <uri>file:///home/truan/Object-Detection/simulation/catkin_ws/src/gazebo_sim/models/Panda arm - Fortress merge include demo/meshes/collision/hand.stl</uri>
            </mesh>
          </geometry>
          <surface>
            <friction>
              <ode>
                <mu>1.05</mu>
                <mu2>1.05</mu2>
              </ode>
            </friction>
          </surface>
        </collision>
        <inertial>
          <pose>-7e-06 0.001524 0.027591 0 -0 0</pose>
          <mass>0.140608</mass>
          <inertia>
            <ixx>0.000536545</ixx>
            <iyy>7.70512e-05</iyy>
            <izz>0.000493818</izz>
            <ixy>1.7912e-08</ixy>
            <ixz>-2.32007e-08</ixz>
            <iyz>4.68115e-08</iyz>
          </inertia>
        </inertial>
      </link>
      <link name='panda_leftfinger'>
        <pose relative_to='panda_finger_joint1'>0 0 0 0 -0 0</pose>
        <visual name='panda_leftfinger_visual'>
          <geometry>
            <mesh>
              <uri>file:///home/truan/Object-Detection/simulation/catkin_ws/src/gazebo_sim/models/Panda arm - Fortress merge include demo/meshes/visual/finger.dae</uri>
            </mesh>
          </geometry>
          <material>
            <diffuse>1 1 1 1</diffuse>
            <specular>1 1 1 1</specular>
          </material>
        </visual>
        <collision name='panda_leftfinger_collision'>
          <geometry>
            <mesh>
              <uri>file:///home/truan/Object-Detection/simulation/catkin_ws/src/gazebo_sim/models/Panda arm - Fortress merge include demo/meshes/collision/finger.stl</uri>
            </mesh>
          </geometry>
          <surface>
            <friction>
              <ode>
                <mu>2.15</mu>
                <mu2>2.15</mu2>
              </ode>
            </friction>
          </surface>
        </collision>
        <inertial>
          <pose>-6e-06 0.002278 -0.027712 0 -0 0</pose>
          <mass>0.223845</mass>
          <inertia>
            <ixx>6.74804e-05</ixx>
            <iyy>6.62719e-05</iyy>
            <izz>1.5504e-05</izz>
            <ixy>-4.10274e-09</ixy>
            <ixz>1.86937e-08</ixz>
            <iyz>1.19675e-05</iyz>
          </inertia>
        </inertial>
      </link>
      <link name='panda_rightfinger'>
        <pose relative_to='panda_finger_joint2'>0 0 0 0 -0 0</pose>
        <visual name='panda_rightfinger_visual'>
          <pose>0 0 0 0 -0 3.14159</pose>
          <geometry>
            <mesh>
              <uri>file:///home/truan/Object-Detection/simulation/catkin_ws/src/gazebo_sim/models/Panda arm - Fortress merge include demo/meshes/visual/finger.dae</uri>
            </mesh>
          </geometry>
          <material>
            <diffuse>1 1 1 1</diffuse>
            <specular>1 1 1 1</specular>
          </material>
        </visual>
        <collision name='panda_rightfinger_collision'>
          <pose>0 0 0 0 -0 3.14159</pose>
          <geometry>
            <mesh>
              <uri>file:///home/truan/Object-Detection/simulation/catkin_ws/src/gazebo_sim/models/Panda arm - Fortress merge include demo/meshes/collision/finger.stl</uri>
            </mesh>
          </geometry>
          <surface>
            <friction>
              <ode>
                <mu>2.15</mu>
                <mu2>2.15</mu2>
              </ode>
            </friction>
          </surface>
        </collision>
        <inertial>
          <pose>-6e-06 0.002278 -0.027712 0 -0 3.14159</pose>
          <mass>0.223845</mass>
          <inertia>
            <ixx>6.74804e-05</ixx>
            <iyy>6.62719e-05</iyy>
            <izz>1.5504e-05</izz>
            <ixy>-4.10274e-09</ixy>
            <ixz>1.86937e-08</ixz>
            <iyz>1.19675e-05</iyz>
          </inertia>
        </inertial>
      </link>
      <joint name='panda_finger_joint1' type='prismatic'>
        <pose relative_to='panda_hand'>0 0 0.0584 0 -0 0</pose>
        <parent>panda_hand</parent>
        <child>panda_leftfinger</child>
        <axis>
          <xyz>0 1 0</xyz>
          <limit>
            <effort>20</effort>
            <lower>0</lower>
            <upper>0.04</upper>
            <velocity>0.2</velocity>
          </limit>
          <dynamics>
            <spring_reference>0</spring_reference>
            <spring_stiffness>0</spring_stiffness>
            <damping>10</damping>
            <friction>0.5</friction>
          </dynamics>
        </axis>
      </joint>
      <joint name='panda_finger_joint2' type='prismatic'>
        <pose relative_to='panda_hand'>0 0 0.0584 0 -0 0</pose>
        <parent>panda_hand</parent>
        <child>panda_rightfinger</child>
        <axis>
          <xyz>0 -1 0</xyz>
          <limit>
            <effort>20</effort>
            <lower>0</lower>
            <upper>0.04</upper>
            <velocity>0.2</velocity>
          </limit>
          <dynamics>
            <spring_reference>0</spring_reference>
            <spring_stiffness>0</spring_stiffness>
            <damping>10</damping>
            <friction>0.5</friction>
          </dynamics>
        </axis>
      </joint>
      <link name='panda_link8'>
        <pose relative_to='end_effector_frame_fixed_joint'>0 0 0 0 -0 0</pose>
      </link>
      <joint name='end_effector_frame_fixed_joint' type='fixed'>
        <pose relative_to='panda_hand'>0 0 0.103 0 -0 0</pose>
        <parent>panda_hand</parent>
        <child>panda_link8</child>
      </joint>
      <plugin name='ignition::gazebo::systems::JointPositionController' filename='ignition-gazebo-joint-position-controller-system'>
        <joint_name>panda_joint1</joint_name>
        <p_gain>50</p_gain>
        <d_gain>20</d_gain>
        <i_gain>0</i_gain>
        <i_min>-1</i_min>
        <i_max>1</i_max>
        <cmd_min>-87</cmd_min>
        <cmd_max>87</cmd_max>
      </plugin>
      <plugin name='ignition::gazebo::systems::JointPositionController' filename='ignition-gazebo-joint-position-controller-system'>
        <joint_name>panda_joint2</joint_name>
        <p_gain>10000</p_gain>
        <d_gain>500</d_gain>
        <i_gain>0</i_gain>
        <i_min>-1</i_min>
        <i_max>1</i_max>
        <cmd_min>-87</cmd_min>
        <cmd_max>87</cmd_max>
      </plugin>
      <plugin name='ignition::gazebo::systems::JointPositionController' filename='ignition-gazebo-joint-position-controller-system'>
        <joint_name>panda_joint3</joint_name>
        <p_gain>100</p_gain>
        <d_gain>10</d_gain>
        <i_gain>0</i_gain>
        <i_min>-1</i_min>
        <i_max>1</i_max>
        <cmd_min>-87</cmd_min>
        <cmd_max>87</cmd_max>
      </plugin>
      <plugin name='ignition::gazebo::systems::JointPositionController' filename='ignition-gazebo-joint-position-controller-system'>
        <joint_name>panda_joint4</joint_name>
        <p_gain>1000</p_gain>
        <d_gain>50</d_gain>
        <i_gain>0</i_gain>
        <i_min>-1</i_min>
        <i_max>1</i_max>
        <cmd_min>-87</cmd_min>
        <cmd_max>87</cmd_max>
      </plugin>
      <plugin name='ignition::gazebo::systems::JointPositionController' filename='ignition-gazebo-joint-position-controller-system'>
        <joint_name>panda_joint5</joint_name>
        <p_gain>100</p_gain>
        <d_gain>50</d_gain>
        <i_gain>0</i_gain>
        <i_min>-1</i_min>
        <i_max>1</i_max>
        <cmd_min>-12</cmd_min>
        <cmd_max>12</cmd_max>
      </plugin>
      <plugin name='ignition::gazebo::systems::JointPositionController' filename='ignition-gazebo-joint-position-controller-system'>
        <joint_name>panda_joint6</joint_name>
        <p_gain>100</p_gain>
        <d_gain>10</d_gain>
        <i_gain>0</i_gain>
        <i_min>-1</i_min>
        <i_max>1</i_max>
        <cmd_min>-12</cmd_min>
        <cmd_max>12</cmd_max>
      </plugin>
      <plugin name='ignition::gazebo::systems::JointPositionController' filename='ignition-gazebo-joint-position-controller-system'>
        <joint_name>panda_joint7</joint_name>
        <p_gain>10</p_gain>
        <d_gain>0.1</d_gain>
        <i_gain>0.5</i_gain>
        <i_min>-1</i_min>
        <i_max>1</i_max>
        <cmd_min>-12</cmd_min>
        <cmd_max>12</cmd_max>
      </plugin>
      <plugin name='ignition::gazebo::systems::JointPositionController' filename='ignition-gazebo-joint-position-controller-system'>
        <joint_name>panda_finger_joint1</joint_name>
        <p_gain>100</p_gain>
        <d_gain>50</d_gain>
        <i_gain>0</i_gain>
        <i_min>-1</i_min>
        <i_max>1</i_max>
        <cmd_min>-20</cmd_min>
        <cmd_max>20</cmd_max>
      </plugin>
      <plugin name='ignition::gazebo::systems::JointPositionController' filename='ignition-gazebo-joint-position-controller-system'>
        <joint_name>panda_finger_joint2</joint_name>
        <p_gain>100</p_gain>
        <d_gain>50</d_gain>
        <i_gain>0</i_gain>
        <i_min>-1</i_min>
        <i_max>1</i_max>
        <cmd_min>-20</cmd_min>
        <cmd_max>20</cmd_max>
      </plugin>
      <pose>0.2 0 1.025 0 -0 0</pose>
    </model>
    <model name='table1'>
      <static>1</static>
      <link name='link'>
        <collision name='surface'>
          <pose>0 0 1 0 -0 0</pose>
          <geometry>
            <box>
              <size>1.5 0.8 0.03</size>
            </box>
          </geometry>
          <surface>
            <friction>
              <ode>
                <mu>0.6</mu>
                <mu2>0.6</mu2>
              </ode>
            </friction>
            <bounce/>
            <contact/>
          </surface>
        </collision>
        <visual name='visual1'>
          <pose>0 0 1 0 -0 0</pose>
          <geometry>
            <box>
              <size>1.5 0.8 0.03</size>
            </box>
          </geometry>
          <material>
            <diffuse>1 1 1 1</diffuse>
            <script>
              <uri>file://media/materials/scripts/gazebo.material</uri>
              <name>Gazebo/Wood</name>
            </script>
            <pbr>
              <metal>
                <albedo_map>https://fuel.ignitionrobotics.org/1.0/openrobotics/models/table/4/files/Table_Diffuse.jpg</albedo_map>
              </metal>
            </pbr>
          </material>
        </visual>
        <collision name='front_left_leg'>
          <pose>0.68 0.38 0.5 0 -0 0</pose>
          <geometry>
            <cylinder>
              <radius>0.02</radius>
              <length>1</length>
            </cylinder>
          </geometry>
          <surface>
            <friction>
              <ode/>
            </friction>
            <bounce/>
            <contact/>
          </surface>
        </collision>
        <visual name='front_left_leg'>
          <pose>0.68 0.38 0.5 0 -0 0</pose>
          <geometry>
            <cylinder>
              <radius>0.02</radius>
              <length>1</length>
            </cylinder>
          </geometry>
          <material>
            <diffuse>0.5 0.5 0.5 1</diffuse>
            <script>
              <uri>file://media/materials/scripts/gazebo.material</uri>
              <name>Gazebo/Grey</name>
            </script>
          </material>
        </visual>
        <collision name='front_right_leg'>
          <pose>0.68 -0.38 0.5 0 -0 0</pose>
          <geometry>
            <cylinder>
              <radius>0.02</radius>
              <length>1</length>
            </cylinder>
          </geometry>
          <surface>
            <friction>
              <ode/>
            </friction>
            <bounce/>
            <contact/>
          </surface>
        </collision>
        <visual name='front_right_leg'>
          <pose>0.68 -0.38 0.5 0 -0 0</pose>
          <geometry>
            <cylinder>
              <radius>0.02</radius>
              <length>1</length>
            </cylinder>
          </geometry>
          <material>
            <diffuse>0.5 0.5 0.5 1</diffuse>
            <script>
              <uri>file://media/materials/scripts/gazebo.material</uri>
              <name>Gazebo/Grey</name>
            </script>
          </material>
        </visual>
        <collision name='back_right_leg'>
          <pose>-0.68 -0.38 0.5 0 -0 0</pose>
          <geometry>
            <cylinder>
              <radius>0.02</radius>
              <length>1</length>
            </cylinder>
          </geometry>
          <surface>
            <friction>
              <ode/>
            </friction>
            <bounce/>
            <contact/>
          </surface>
        </collision>
        <visual name='back_right_leg'>
          <pose>-0.68 -0.38 0.5 0 -0 0</pose>
          <geometry>
            <cylinder>
              <radius>0.02</radius>
              <length>1</length>
            </cylinder>
          </geometry>
          <material>
            <diffuse>0.5 0.5 0.5 1</diffuse>
            <script>
              <uri>file://media/materials/scripts/gazebo.material</uri>
              <name>Gazebo/Grey</name>
            </script>
          </material>
        </visual>
        <collision name='back_left_leg'>
          <pose>-0.68 0.38 0.5 0 -0 0</pose>
          <geometry>
            <cylinder>
              <radius>0.02</radius>
              <length>1</length>
            </cylinder>
          </geometry>
          <surface>
            <friction>
              <ode/>
            </friction>
            <bounce/>
            <contact/>
          </surface>
        </collision>
        <visual name='back_left_leg'>
          <pose>-0.68 0.38 0.5 0 -0 0</pose>
          <geometry>
            <cylinder>
              <radius>0.02</radius>
              <length>1</length>
            </cylinder>
          </geometry>
          <material>
            <diffuse>0.5 0.5 0.5 1</diffuse>
            <script>
              <uri>file://media/materials/scripts/gazebo.material</uri>
              <name>Gazebo/Grey</name>
            </script>
          </material>
        </visual>
      </link>
      <pose>0 0 0 0 -0 1.5708</pose>
    </model>
    <model name='table2'>
      <static>1</static>
      <link name='link'>
        <collision name='surface'>
          <pose>0 0 1 0 -0 0</pose>
          <geometry>
            <box>
              <size>1.5 0.8 0.03</size>
            </box>
          </geometry>
          <surface>
            <friction>
              <ode>
                <mu>0.6</mu>
                <mu2>0.6</mu2>
              </ode>
            </friction>
            <bounce/>
            <contact/>
          </surface>
        </collision>
        <visual name='visual1'>
          <pose>0 0 1 0 -0 0</pose>
          <geometry>
            <box>
              <size>1.5 0.8 0.03</size>
            </box>
          </geometry>
          <material>
            <diffuse>1 1 1 1</diffuse>
            <script>
              <uri>file://media/materials/scripts/gazebo.material</uri>
              <name>Gazebo/Wood</name>
            </script>
            <pbr>
              <metal>
                <albedo_map>https://fuel.ignitionrobotics.org/1.0/openrobotics/models/table/4/files/Table_Diffuse.jpg</albedo_map>
              </metal>
            </pbr>
          </material>
        </visual>
        <collision name='front_left_leg'>
          <pose>0.68 0.38 0.5 0 -0 0</pose>
          <geometry>
            <cylinder>
              <radius>0.02</radius>
              <length>1</length>
            </cylinder>
          </geometry>
          <surface>
            <friction>
              <ode/>
            </friction>
            <bounce/>
            <contact/>
          </surface>
        </collision>
        <visual name='front_left_leg'>
          <pose>0.68 0.38 0.5 0 -0 0</pose>
          <geometry>
            <cylinder>
              <radius>0.02</radius>
              <length>1</length>
            </cylinder>
          </geometry>
          <material>
            <diffuse>0.5 0.5 0.5 1</diffuse>
            <script>
              <uri>file://media/materials/scripts/gazebo.material</uri>
              <name>Gazebo/Grey</name>
            </script>
          </material>
        </visual>
        <collision name='front_right_leg'>
          <pose>0.68 -0.38 0.5 0 -0 0</pose>
          <geometry>
            <cylinder>
              <radius>0.02</radius>
              <length>1</length>
            </cylinder>
          </geometry>
          <surface>
            <friction>
              <ode/>
            </friction>
            <bounce/>
            <contact/>
          </surface>
        </collision>
        <visual name='front_right_leg'>
          <pose>0.68 -0.38 0.5 0 -0 0</pose>
          <geometry>
            <cylinder>
              <radius>0.02</radius>
              <length>1</length>
            </cylinder>
          </geometry>
          <material>
            <diffuse>0.5 0.5 0.5 1</diffuse>
            <script>
              <uri>file://media/materials/scripts/gazebo.material</uri>
              <name>Gazebo/Grey</name>
            </script>
          </material>
        </visual>
        <collision name='back_right_leg'>
          <pose>-0.68 -0.38 0.5 0 -0 0</pose>
          <geometry>
            <cylinder>
              <radius>0.02</radius>
              <length>1</length>
            </cylinder>
          </geometry>
          <surface>
            <friction>
              <ode/>
            </friction>
            <bounce/>
            <contact/>
          </surface>
        </collision>
        <visual name='back_right_leg'>
          <pose>-0.68 -0.38 0.5 0 -0 0</pose>
          <geometry>
            <cylinder>
              <radius>0.02</radius>
              <length>1</length>
            </cylinder>
          </geometry>
          <material>
            <diffuse>0.5 0.5 0.5 1</diffuse>
            <script>
              <uri>file://media/materials/scripts/gazebo.material</uri>
              <name>Gazebo/Grey</name>
            </script>
          </material>
        </visual>
        <collision name='back_left_leg'>
          <pose>-0.68 0.38 0.5 0 -0 0</pose>
          <geometry>
            <cylinder>
              <radius>0.02</radius>
              <length>1</length>
            </cylinder>
          </geometry>
          <surface>
            <friction>
              <ode/>
            </friction>
            <bounce/>
            <contact/>
          </surface>
        </collision>
        <visual name='back_left_leg'>
          <pose>-0.68 0.38 0.5 0 -0 0</pose>
          <geometry>
            <cylinder>
              <radius>0.02</radius>
              <length>1</length>
            </cylinder>
          </geometry>
          <material>
            <diffuse>0.5 0.5 0.5 1</diffuse>
            <script>
              <uri>file://media/materials/scripts/gazebo.material</uri>
              <name>Gazebo/Grey</name>
            </script>
          </material>
        </visual>
      </link>
      <pose>0.794 0 0 0 -0 1.5708</pose>
    </model>
    <model name='Transformers_Age_of_Extinction_Mega_1Step_Bumblebee_Figure'>
      <link name='link_0'>
        <visual name='visual'>
          <geometry>
            <mesh>
              <uri>file:///home/truan/.ignition/fuel/fuel.ignitionrobotics.org/googleresearch/models/transformers_age_of_extinction_mega_1step_bumblebee_figure/1/meshes/model.obj</uri>
            </mesh>
          </geometry>
        </visual>
        <collision name='collision_0'>
          <geometry>
            <mesh>
              <uri>file:///home/truan/.ignition/fuel/fuel.ignitionrobotics.org/googleresearch/models/transformers_age_of_extinction_mega_1step_bumblebee_figure/1/meshes/model.obj</uri>
            </mesh>
          </geometry>
        </collision>
      </link>
      <pose>0.995781 -0.277315 1.01771 0.165736 -0.016873 -2.6308</pose>
    </model>
    <model name='Avengers_Thor_PLlrpYniaeB'>
      <link name='link_0'>
        <visual name='visual'>
          <geometry>
            <mesh>
              <uri>file:///home/truan/.ignition/fuel/fuel.ignitionrobotics.org/googleresearch/models/avengers_thor_pllrpyniaeb/1/meshes/model.obj</uri>
            </mesh>
          </geometry>
        </visual>
        <collision name='collision_0'>
          <geometry>
            <mesh>
              <uri>file:///home/truan/.ignition/fuel/fuel.ignitionrobotics.org/googleresearch/models/avengers_thor_pllrpyniaeb/1/meshes/model.obj</uri>
            </mesh>
          </geometry>
        </collision>
      </link>
      <pose>0.999999 0.499999 1.01405 -0.004648 0.006036 -4.8e-05</pose>
    </model>
    <model name='My_Little_Pony_Princess_Celestia'>
      <link name='link_0'>
        <visual name='visual'>
          <geometry>
            <mesh>
              <uri>file:///home/truan/.ignition/fuel/fuel.ignitionrobotics.org/googleresearch/models/my_little_pony_princess_celestia/1/meshes/model.obj</uri>
            </mesh>
          </geometry>
        </visual>
        <collision name='collision_0'>
          <geometry>
            <mesh>
              <uri>file:///home/truan/.ignition/fuel/fuel.ignitionrobotics.org/googleresearch/models/my_little_pony_princess_celestia/1/meshes/model.obj</uri>
            </mesh>
          </geometry>
        </collision>
      </link>
      <pose>0.999999 -0.499999 1.01469 -0.000919 -0.010092 1.57102</pose>
    </model>
  </world>
</sdf>
