<?xml version='1.0'?>
<sdf version='1.7'>
  <model name='cart_model2'>
    <pose>0 0 0 0 0 0</pose>
    <!-- BASE_LINK FRAME -->
    <link name='base_link'>
      <pose>0 0 0 0 0 -1.57079632679</pose>
      <inertial>
        <pose>0 -0.5 0.5 0 0 0</pose>
        <mass>90</mass>
        <inertia>
          <ixx>0.1</ixx>
          <ixy>0</ixy>
          <ixz>0</ixz>
          <iyy>0.1</iyy>
          <iyz>0</iyz>
          <izz>0.1</izz>
        </inertia>
      </inertial>
      <collision name='base_link_collision'>
        <pose>0 0 0 0 0 0</pose>
        <geometry>
          <mesh>
            <scale>2 1 1</scale>
            <uri>meshes/cart_base_collision.stl</uri>
          </mesh>
        </geometry>
        <max_contacts>5</max_contacts>
        <surface>
          <contact>
            <ode>
              <soft_cfm>1.0</soft_cfm>
              <soft_erp>0.4</soft_erp>
              <kp>1000000.0</kp>
              <kd>1</kd>
              <min_depth>0.01</min_depth>
            </ode>
          </contact>
          <friction>
            <ode>
              <mu>1.16</mu>
              <mu2>1.16</mu2>
            </ode>
          </friction>
        </surface>
      </collision>
      <visual name='base_link_visual'>
        <pose>0 0 0 0 0 0</pose>
        <geometry>
          <mesh>
            <scale>2 1 1</scale>
            <uri>meshes/cart_base.dae</uri>
            <submesh>
              <name>base_metal</name>
              <center>false</center>
            </submesh>
          </mesh>
        </geometry>
      </visual>
      <visual name='base_shelf_visual'>
        <pose>0 0 0 0 0 0</pose>
        <geometry>
          <mesh>
            <scale>2 1 1</scale>
            <uri>meshes/cart_base.dae</uri>
            <submesh>
              <name>base_shelf</name>
              <center>false</center>
            </submesh>
          </mesh>
        </geometry>
      </visual>
      <visual name="back_left_sup_visual">
        <pose>-0.245 -1.005 0.05 0 0 0</pose>
        <geometry>
          <mesh>
            <scale>2 2 2</scale>
            <uri>meshes/sup_wheels.dae</uri>
          </mesh>
        </geometry>
      </visual>
      <visual name="back_right_sup_visual">
        <pose>0.245 -1.005 0.05 0 0 0</pose>
        <geometry>
          <mesh>
            <scale>2 2 2</scale>
            <uri>meshes/sup_wheels.dae</uri>
          </mesh>
        </geometry>
      </visual>
      <visual name='tag_visual'>
        <pose>0 0 0 0 0 0</pose>
        <geometry>
          <mesh>
            <scale>4 4 4</scale>
            <uri>meshes/cart_base.dae</uri>
            <submesh>
              <name>tag</name>
              <center>false</center>
            </submesh>
          </mesh>
        </geometry>
        <material>
          <diffuse>1.0 1.0 1.0</diffuse>
          <specular>1.0 1.0 1.0</specular>
          <pbr>
            <metal>
              <albedo_map>meshes/cart_tag.png</albedo_map>
            </metal>
          </pbr>
        </material>
      </visual>
    </link>

    <!-- Wheels -->

    <!-- Back Left -->
    <link name="back_left">
      <pose>-1.04 -0.49 -0.05 0 0 1.570796327</pose>
      <inertial>
        <pose>0 0 0 0 1.570796327 0</pose>
        <mass>0.01</mass>
        <inertia>
          <ixx>0.0000175</ixx>
          <ixy>0</ixy>
          <ixz>0</ixz>
          <iyy>0.0000175</iyy>
          <iyz>0</iyz>
          <izz>0.00003125</izz>
        </inertia>
      </inertial>
      <collision name="back_left_collision">
        <pose>0 0 0 0 1.570796327 0</pose>
        <geometry>
          <cylinder>
            <length>0.5</length>
            <radius>0.5</radius>
          </cylinder>
        </geometry>
        <max_contacts>5</max_contacts>
        <surface>
          <contact>
            <ode>
              <soft_cfm>1.0</soft_cfm>
              <soft_erp>0.4</soft_erp>
              <kp>1000000.0</kp>
              <kd>1</kd>
              <min_depth>0.01</min_depth>
            </ode>
          </contact>
          <friction>
            <ode>
              <mu>1.16</mu>
              <mu2>1.16</mu2>
            </ode>
          </friction>
        </surface>
      </collision>
      <visual name="back_left_visual">
        <pose>0 0 0 0 0 0</pose>
        <geometry>
          <mesh>
            <scale>4 4 4</scale>
            <uri>meshes/wheel.dae</uri>
          </mesh>
        </geometry>
      </visual>
    </link>

    <joint name="back_left_joint" type="revolute">
      <child>back_left</child>
      <parent>base_link</parent>
      <axis>
        <xyz>1 0 0</xyz>
        <dynamics>
          <friction>0.5</friction>
          <damping>0.0001</damping>
        </dynamics>
      </axis>
    </joint>

    <!-- Back Right -->
    <link name="back_right">
      <pose>-1.04 0.49 -0.05 0 0 1.570796327</pose>
      <inertial>
        <pose>0 0 0 0 1.570796327 0</pose>
        <mass>0.01</mass>
        <inertia>
          <ixx>0.0000175</ixx>
          <ixy>0</ixy>
          <ixz>0</ixz>
          <iyy>0.0000175</iyy>
          <iyz>0</iyz>
          <izz>0.00003125</izz>
        </inertia>
      </inertial>
      <collision name="back_right_collision">
        <pose>0 0 0 0 1.570796327 0</pose>
        <geometry>
          <cylinder>
            <length>0.5</length>
            <radius>0.5</radius>
          </cylinder>
        </geometry>
        <max_contacts>5</max_contacts>
        <surface>
          <contact>
            <ode>
              <soft_cfm>1.0</soft_cfm>
              <soft_erp>0.4</soft_erp>
              <kp>1000000.0</kp>
              <kd>1</kd>
              <min_depth>0.01</min_depth>
            </ode>
          </contact>
          <friction>
            <ode>
              <mu>1.16</mu>
              <mu2>1.16</mu2>
            </ode>
          </friction>
        </surface>
      </collision>
      <visual name="back_right_visual">
        <pose>0 0 0 0 0 0</pose>
        <geometry>
          <mesh>
            <scale>4 4 4</scale>
            <uri>meshes/wheel.dae</uri>
          </mesh>
        </geometry>
      </visual>
    </link>

    <joint name="back_right_joint" type="revolute">
      <child>back_right</child>
      <parent>base_link</parent>
      <axis>
        <xyz>1 0 0</xyz>
        <dynamics>
          <friction>0.5</friction>
          <damping>0.0001</damping>
        </dynamics>
      </axis>
    </joint>

    <!-- Front Left -->

    <link name="front_left">
      <pose>-0.04 -0.49 -0.05 0 0 1.570796327</pose>
      <inertial>
        <pose>0 0 0 0 1.570796327 0</pose>
        <mass>0.01</mass>
        <inertia>
          <ixx>0.0000175</ixx>
          <ixy>0</ixy>
          <ixz>0</ixz>
          <iyy>0.0000175</iyy>
          <iyz>0</iyz>
          <izz>0.00003125</izz>
        </inertia>
      </inertial>
      <collision name="front_left_collision">
        <pose>0 0 0 0 1.570796327 0</pose>
        <geometry>
          <cylinder>
            <length>0.5</length>
            <radius>0.5</radius>
          </cylinder>
        </geometry>
        <max_contacts>5</max_contacts>
        <surface>
          <contact>
            <ode>
              <soft_cfm>1.0</soft_cfm>
              <soft_erp>0.4</soft_erp>
              <kp>1000000.0</kp>
              <kd>1</kd>
              <min_depth>0.01</min_depth>
            </ode>
          </contact>
          <friction>
            <ode>
              <mu>1.16</mu>
              <mu2>1.16</mu2>
            </ode>
          </friction>
        </surface>
      </collision>
      <visual name="front_left_visual">
        <pose>0 0 0 0 0 0</pose>
        <geometry>
          <mesh>
            <scale>4 4 4</scale>
            <uri>meshes/wheel.dae</uri>
          </mesh>
        </geometry>
      </visual>
    </link>

    <joint name="front_left_joint" type="revolute">
      <child>front_left</child>
      <parent>base_link</parent>
      <axis>
        <xyz>1 0 0</xyz>
        <dynamics>
          <friction>0.5</friction>
          <damping>0.0001</damping>
        </dynamics>
      </axis>
    </joint>

    <!-- Front Right -->
    <link name="front_right">
      <pose>-0.04 0.49 -0.05 0 0 1.570796327</pose>
      <inertial>
        <pose>0 0 0 0 1.570796327 0</pose>
        <mass>0.01</mass>
        <inertia>
          <ixx>0.0000175</ixx>
          <ixy>0</ixy>
          <ixz>0</ixz>
          <iyy>0.0000175</iyy>
          <iyz>0</iyz>
          <izz>0.00003125</izz>
        </inertia>
      </inertial>
      <collision name="front_right_collision">
        <pose>0 0 0 0 1.570796327 0</pose>
        <geometry>
          <cylinder>
            <length>0.5</length>
            <radius>0.5</radius>
          </cylinder>
        </geometry>
        <max_contacts>5</max_contacts>
        <surface>
          <contact>
            <ode>
              <soft_cfm>1.0</soft_cfm>
              <soft_erp>0.4</soft_erp>
              <kp>1000000.0</kp>
              <kd>1</kd>
              <min_depth>0.01</min_depth>
            </ode>
          </contact>
          <friction>
            <ode>
              <mu>1.16</mu>
              <mu2>1.16</mu2>
            </ode>
          </friction>
        </surface>
      </collision>
      <visual name="front_right_visual">
        <pose>0 0 0 0 0 0</pose>
        <geometry>
          <mesh>
            <scale>4 4 4</scale>
            <uri>meshes/wheel.dae</uri>
          </mesh>
        </geometry>
      </visual>
    </link>

    <joint name="front_right_joint" type="revolute">
      <child>front_right</child>
      <parent>base_link</parent>
      <axis>
        <xyz>1 0 0</xyz>
        <dynamics>
          <friction>0.5</friction>
          <damping>0.0001</damping>
        </dynamics>
      </axis>
    </joint>

    <!--Allow user to control the wheel and publish the control message to the user controller interface-->
    <plugin name='ignition::gazebo::systems::DiffDrive' filename='ignition-gazebo-diff-drive-system'>
      <ros>
        <namespace>/mobile_robot_with_arm</namespace>
        <remapping>cmd_vel:=cmd_vel</remapping>
        <remapping>odom:=odom</remapping>
      </ros>
      <left_joint>front_left_joint</left_joint>
      <left_joint>back_left_joint</left_joint>
      <right_joint>front_right_joint</right_joint>
      <right_joint>back_right_joint</right_joint>
      <wheel_separation>1.47</wheel_separation>
      <wheel_diameter>1</wheel_diameter>
      <max_wheel_torque>5</max_wheel_torque>
      <max_wheel_acceleration>5</max_wheel_acceleration>
      <publish_odom>1</publish_odom>
      <publish_odom_tf>1</publish_odom_tf>
      <publish_wheel_tf>1</publish_wheel_tf>
      <odometry_frame>odom</odometry_frame>
      <robot_base_frame>base_link</robot_base_frame>
    </plugin>
  </model>
</sdf>
