<sdf version='1.7'>
  <world name='world_demo'>
    <gravity>0 0 -9.8</gravity>
    <physics type='ode'>
      <max_step_size>0.01</max_step_size>
      <real_time_factor>1</real_time_factor>
      <max_contacts>10</max_contacts>
      <real_time_update_rate>1000</real_time_update_rate>
    </physics>
    <plugin name='ignition::gazebo::systems::Physics' filename='libignition-gazebo-physics-system.so'/>
    <plugin name='ignition::gazebo::systems::UserCommands' filename='libignition-gazebo-user-commands-system.so'/>
    <plugin name='ignition::gazebo::systems::SceneBroadcaster' filename='libignition-gazebo-scene-broadcaster-system.so'/>
    <plugin name='ignition::gazebo::systems::Imu' filename='ignition-gazebo-imu-system'/>
    <plugin name='ignition::gazebo::systems::Sensors' filename='ignition-gazebo-sensors-system'>
      <render_engine>ogre2</render_engine>
    </plugin>
    <gui fullscreen='0'>
      <plugin name='3D View' filename='GzScene3D'>
        <ignition-gui>
          <title>3D View</title>
          <property type='bool' key='showTitleBar'>0</property>
          <property type='string' key='state'>docked</property>
        </ignition-gui>
        <engine>ogre2</engine>
        <scene>scene</scene>
        <ambient_light>0.4 0.4 0.4</ambient_light>
        <background_color>0.8 0.8 0.8</background_color>
        <camera_pose>13.4 -6.1 2.23 0 0.4 -1.83</camera_pose>
      </plugin>
      <plugin name='World control' filename='WorldControl'>
        <ignition-gui>
          <title>World control</title>
          <property type='bool' key='showTitleBar'>0</property>
          <property type='bool' key='resizable'>0</property>
          <property type='double' key='height'>72</property>
          <property type='double' key='width'>121</property>
          <property type='double' key='z'>1</property>
          <property type='string' key='state'>floating</property>
          <anchors target='3D View'>
            <line own='left' target='left'/>
            <line own='bottom' target='bottom'/>
          </anchors>
        </ignition-gui>
        <play_pause>1</play_pause>
        <step>1</step>
        <start_paused>1</start_paused>
      </plugin>
      <plugin name='World stats' filename='WorldStats'>
        <ignition-gui>
          <title>World stats</title>
          <property type='bool' key='showTitleBar'>0</property>
          <property type='bool' key='resizable'>0</property>
          <property type='double' key='height'>110</property>
          <property type='double' key='width'>290</property>
          <property type='double' key='z'>1</property>
          <property type='string' key='state'>floating</property>
          <anchors target='3D View'>
            <line own='right' target='right'/>
            <line own='bottom' target='bottom'/>
          </anchors>
        </ignition-gui>
        <sim_time>1</sim_time>
        <real_time>1</real_time>
        <real_time_factor>1</real_time_factor>
        <iterations>1</iterations>
      </plugin>
      <plugin name='Transform control' filename='TransformControl'>
        <ignition-gui>
          <property type='bool' key='showTitleBar'>0</property>
          <property key='x' type='double'>0</property>
          <property key='y' type='double'>0</property>
          <property key='width' type='double'>250</property>
          <property key='height' type='double'>50</property>
          <property key='state' type='string'>floating</property>
          <property key='cardBackground' type='string'>#666666</property>
        </ignition-gui>
      </plugin>
      <plugin name='Shapes' filename='Shapes'>
        <ignition-gui>
          <property type='bool' key='showTitleBar'>0</property>
          <property key='x' type='double'>250</property>
          <property key='y' type='double'>0</property>
          <property key='width' type='double'>150</property>
          <property key='height' type='double'>50</property>
          <property key='state' type='string'>floating</property>
          <property key='cardBackground' type='string'>#666666</property>
        </ignition-gui>
      </plugin>
      <plugin name='Screenshot' filename='Screenshot'>
        <ignition-gui>
          <property type='bool' key='showTitleBar'>0</property>
          <property key='x' type='double'>400</property>
          <property key='y' type='double'>0</property>
          <property key='width' type='double'>50</property>
          <property key='height' type='double'>50</property>
          <property key='state' type='string'>floating</property>
          <property key='cardBackground' type='string'>#666666</property>
        </ignition-gui>
      </plugin>
      <plugin name='Component inspector' filename='ComponentInspector'>
        <ignition-gui>
          <property key='x' type='double'>0</property>
          <property key='y' type='double'>0</property>
          <property key='width' type='double'>400</property>
          <property key='height' type='double'>375</property>
          <property key='state' type='string'>docked_collapsed</property>
        </ignition-gui>
      </plugin>
      <plugin name='Entity tree' filename='EntityTree'>
        <ignition-gui>
          <property key='x' type='double'>0</property>
          <property key='y' type='double'>0</property>
          <property key='width' type='double'>400</property>
          <property key='height' type='double'>375</property>
          <property key='state' type='string'>docked_collapsed</property>
        </ignition-gui>
      </plugin>
      <plugin name='Teleop' filename='Teleop'>
        <ignition-gui>
          <property key='x' type='double'>0</property>
          <property key='y' type='double'>0</property>
          <property key='width' type='double'>400</property>
          <property key='height' type='double'>900</property>
          <property key='state' type='string'>docked</property>
        </ignition-gui>
        <topic>/model/tugbot/cmd_vel</topic>
      </plugin>
    </gui>
    <scene>
      <ambient>1 1 1 1</ambient>
      <background>0.3 0.7 0.9 1</background>
      <shadows>0</shadows>
      <grid>0</grid>
    </scene>
    <light name='sun' type='directional'>
      <cast_shadows>0</cast_shadows>
      <pose>-5 -3 10 0 -0 0</pose>
      <diffuse>1 1 1 1</diffuse>
      <specular>1 1 1 1</specular>
      <direction>0 0 -1</direction>
      <attenuation>
        <range>10</range>
      </attenuation>
      <spot>
        <inner_angle>0</inner_angle>
        <outer_angle>0</outer_angle>
        <falloff>0</falloff>
      </spot>
    </light>
    <magnetic_field>6e-06 2.3e-05 -4.2e-05</magnetic_field>
    <atmosphere type='adiabatic'/>
    <model name='ground_plane'>
      <static>1</static>
      <link name='link'>
        <collision name='collision'>
          <geometry>
            <plane>
              <normal>0 0 1</normal>
              <size>1 1</size>
            </plane>
          </geometry>
          <surface>
            <friction>
              <ode/>
            </friction>
            <bounce/>
            <contact/>
          </surface>
        </collision>
      </link>
      <pose>0 0 0 0 -0 0</pose>
    </model>
    <model name='warehouse'>
      <pose>0 0 -0.09 0 -0 0</pose>
      <self_collide>0</self_collide>
      <link name='warehouse_base'>
        <pose>0 0 0 0 -0 0</pose>
        <collision name='warehouse_collision'>
          <pose>0 0 0 0 -0 0</pose>
          <geometry>
            <mesh>
              <scale>1 1 1</scale>
              <uri>file:///home/truan/.ignition/fuel/fuel.ignitionrobotics.org/openrobotics/models/warehouse/5/meshes/warehouse_colision.stl</uri>
            </mesh>
          </geometry>
        </collision>
        <visual name='warehouse_visual'>
          <pose>0 0 0 0 -0 0</pose>
          <geometry>
            <mesh>
              <scale>1 1 1</scale>
              <uri>file:///home/truan/.ignition/fuel/fuel.ignitionrobotics.org/openrobotics/models/warehouse/5/meshes/warehouse.dae</uri>
            </mesh>
          </geometry>
        </visual>
        <visual name='drop_area_visual'>
          <pose>0 0 0.101 0 -0 0</pose>
          <geometry>
            <mesh>
              <scale>1 1 1</scale>
              <uri>file:///home/truan/.ignition/fuel/fuel.ignitionrobotics.org/openrobotics/models/warehouse/5/meshes/warehouse.dae</uri>
              <submesh>
                <name>drop1</name>
                <center>1</center>
              </submesh>
            </mesh>
          </geometry>
        </visual>
      </link>
      <static>1</static>
    </model>
    <model name='charging_station'>
      <pose>14.7 -10.6 -0.04 0 -0 0</pose>
      <link name='charging_station_base_link'>
        <pose>0 0 0.05 0 0 -1.5708</pose>
        <collision name='charging_station_collision'>
          <pose>0 0 0.3 0 0 -1.5708</pose>
          <geometry>
            <box>
              <size>0.1 0.55 0.4</size>
            </box>
          </geometry>
          <surface>
            <friction>
              <ode/>
            </friction>
            <bounce/>
            <contact/>
          </surface>
        </collision>
        <visual name='charging_station_visual'>
          <pose>0 0 0 0 -0 0</pose>
          <geometry>
            <mesh>
              <scale>1 1 1</scale>
              <uri>file:///home/truan/.ignition/fuel/fuel.ignitionrobotics.org/movai/models/tugbot-charging-station/2/meshes/charging_station.dae</uri>
            </mesh>
          </geometry>
        </visual>
      </link>
      <static>1</static>
    </model>
    <model name='tugbot'>
      <self_collide>0</self_collide>
      <pose>13.9 -10.6 0.1 0 -0 0</pose>
      <static>0</static>
      <link name='base_link'>
        <pose>0 0 0 0 -0 0</pose>
        <inertial>
          <pose>-0.1 0 0.1 0 -0 0</pose>
          <mass>46.2</mass>
          <inertia>
            <ixx>1.55925</ixx>
            <ixy>0</ixy>
            <ixz>0</ixz>
            <iyy>1.55925</iyy>
            <iyz>0</iyz>
            <izz>1.55925</izz>
          </inertia>
        </inertial>
        <collision name='base_link_collision'>
          <pose>0 0 0 0 -0 0</pose>
          <geometry>
            <mesh>
              <uri>file:///home/truan/.ignition/fuel/fuel.ignitionrobotics.org/movai/models/tugbot/1/meshes/base/tugbot_simp.stl</uri>
            </mesh>
          </geometry>
        </collision>
        <visual name='base_link_visual'>
          <pose>0 0 0 0 -0 0</pose>
          <geometry>
            <mesh>
              <uri>file:///home/truan/.ignition/fuel/fuel.ignitionrobotics.org/movai/models/tugbot/1/meshes/base/tugbot_simp.dae</uri>
            </mesh>
          </geometry>
        </visual>
        <visual name='movai_logo_visual'>
          <pose>0 0 0 0 -0 0</pose>
          <geometry>
            <mesh>
              <uri>file:///home/truan/.ignition/fuel/fuel.ignitionrobotics.org/movai/models/tugbot/1/meshes/base/movai_logo.dae</uri>
            </mesh>
          </geometry>
          <material>
            <diffuse>1 1 1 1</diffuse>
            <pbr>
              <metal>
                <albedo_map>meshes/base/movai-logo.png</albedo_map>
              </metal>
            </pbr>
          </material>
        </visual>
        <visual name='light_link_visual'>
          <pose>-0.1 0 0.1945 0 1.5708 0</pose>
          <geometry>
            <mesh>
              <scale>1 1 1</scale>
              <uri>file:///home/truan/.ignition/fuel/fuel.ignitionrobotics.org/movai/models/tugbot/1/meshes/light_link/light_led.stl</uri>
            </mesh>
          </geometry>
          <material>
            <ambient>0 0 0 1</ambient>
            <diffuse>0 0 0 1</diffuse>
            <specular>0 0 0 1</specular>
            <emissive>0 1 0 1</emissive>
          </material>
        </visual>
        <visual name='warnign_light_visual'>
          <pose>-0.099 0 0.195 0 1.5708 0</pose>
          <geometry>
            <mesh>
              <scale>1.02 1.02 1.02</scale>
              <uri>file:///home/truan/.ignition/fuel/fuel.ignitionrobotics.org/movai/models/tugbot/1/meshes/light_link/light.stl</uri>
            </mesh>
          </geometry>
          <material>
            <ambient>0.1 0.05 0 0.5</ambient>
            <diffuse>1 0.5 0 0.5</diffuse>
            <specular>1 0.5 0 0.5</specular>
            <emissive>1 0.5 0 0.5</emissive>
          </material>
        </visual>
      </link>
      <link name='imu_link'>
        <pose>0.14 0.02 0.25 0 0 -1.57</pose>
        <sensor name='imu' type='imu'>
          <update_rate>30</update_rate>
          <visualize>0</visualize>
          <imu/>
        </sensor>
      </link>
      <joint name='imu_link_joint' type='fixed'>
        <child>imu_link</child>
        <parent>base_link</parent>
      </joint>
      <link name='warnign_light'>
        <pose>-0.185 0 0.46 0 -0 0</pose>
        <inertial>
          <pose>0 0 0 0 -0 0</pose>
          <mass>0.1</mass>
          <inertia>
            <ixx>1.6875e-05</ixx>
            <ixy>0</ixy>
            <ixz>0</ixz>
            <iyy>1e-08</iyy>
            <iyz>0</iyz>
            <izz>1.6875e-05</izz>
          </inertia>
        </inertial>
        <light name='warnign_light_lamp' type='spot'>
          <pose>-0.04 0 0 0 1.5708 0</pose>
          <attenuation>
            <range>5</range>
            <linear>0</linear>
            <constant>0.1</constant>
            <quadratic>0.0025</quadratic>
          </attenuation>
          <diffuse>1 0.5 0 1</diffuse>
          <specular>1 0.5 0 1</specular>
          <spot>
            <inner_angle>0.9</inner_angle>
            <outer_angle>1</outer_angle>
            <falloff>2</falloff>
          </spot>
          <direction>0 0 -1</direction>
          <cast_shadows>1</cast_shadows>
        </light>
      </link>
      <joint name='warnign_light_joint' type='revolute'>
        <child>warnign_light</child>
        <parent>base_link</parent>
        <axis>
          <xyz>0 0 1</xyz>
          <limit>
            <effort>1000</effort>
            <velocity>20</velocity>
            <lower>-1e+16</lower>
            <upper>1e+16</upper>
          </limit>
        </axis>
      </joint>
      <link name='camera_front'>
        <pose relative_to='base_link'>0.0553 0 0.4323 0 -0 0</pose>
        <sensor name='color' type='camera'>
          <pose>0 0.0325 0.0125 0 -0 0</pose>
          <update_rate>6</update_rate>
          <always_on>0</always_on>
          <camera>
            <horizontal_fov>1.20428</horizontal_fov>
            <image>
              <width>848</width>
              <height>480</height>
            </image>
            <clip>
              <near>0.1</near>
              <far>50</far>
            </clip>
            <lens>
              <intrinsics>
                <fx>615.96</fx>
                <fy>616.227</fy>
                <cx>419.83</cx>
                <cy>245.143</cy>
                <s>0</s>
              </intrinsics>
              <type>stereographic</type>
              <scale_to_hfov>1</scale_to_hfov>
            </lens>
          </camera>
        </sensor>
        <sensor name='depth' type='depth_camera'>
          <pose>0 0.0175 0.0125 0 -0 0</pose>
          <update_rate>6</update_rate>
          <always_on>0</always_on>
          <camera>
            <horizontal_fov>1.51844</horizontal_fov>
            <image>
              <width>848</width>
              <height>480</height>
              <format>R_FLOAT32</format>
            </image>
            <clip>
              <near>0.1</near>
              <far>10</far>
            </clip>
            <lens>
              <intrinsics>
                <fx>421.616</fx>
                <fy>421.616</fy>
                <cx>422.285</cx>
                <cy>236.572</cy>
                <s>0</s>
              </intrinsics>
              <type>stereographic</type>
              <scale_to_hfov>1</scale_to_hfov>
            </lens>
          </camera>
        </sensor>
      </link>
      <joint name='camera_front_joint' type='fixed'>
        <child>camera_front</child>
        <parent>base_link</parent>
      </joint>
      <link name='camera_back'>
        <pose relative_to='base_link'>-0.241 0 0.2303 0 -0 -3.14159</pose>
        <sensor name='color' type='camera'>
          <pose>0 0.0325 0.0125 0 -0 0</pose>
          <update_rate>6</update_rate>
          <always_on>0</always_on>
          <camera>
            <horizontal_fov>1.20428</horizontal_fov>
            <image>
              <width>848</width>
              <height>480</height>
            </image>
            <clip>
              <near>0.1</near>
              <far>50</far>
            </clip>
            <lens>
              <intrinsics>
                <fx>615.96</fx>
                <fy>616.227</fy>
                <cx>419.83</cx>
                <cy>245.143</cy>
                <s>0</s>
              </intrinsics>
              <type>stereographic</type>
              <scale_to_hfov>1</scale_to_hfov>
            </lens>
          </camera>
        </sensor>
        <sensor name='depth' type='depth_camera'>
          <pose>0 0.0175 0.0125 0 -0 0</pose>
          <update_rate>6</update_rate>
          <always_on>0</always_on>
          <camera>
            <horizontal_fov>1.51844</horizontal_fov>
            <image>
              <width>848</width>
              <height>480</height>
              <format>R_FLOAT32</format>
            </image>
            <clip>
              <near>0.1</near>
              <far>10</far>
            </clip>
            <lens>
              <intrinsics>
                <fx>421.616</fx>
                <fy>421.616</fy>
                <cx>422.285</cx>
                <cy>236.572</cy>
                <s>0</s>
              </intrinsics>
              <type>stereographic</type>
              <scale_to_hfov>1</scale_to_hfov>
            </lens>
          </camera>
        </sensor>
      </link>
      <joint name='camera_back_joint' type='fixed'>
        <child>camera_back</child>
        <parent>base_link</parent>
      </joint>
      <link name='scan_front'>
        <pose>0.221 0 0.1404 0 -0 0</pose>
        <sensor name='scan_front' type='gpu_lidar'>
          <update_rate>10</update_rate>
          <lidar>
            <scan>
              <horizontal>
                <samples>674</samples>
                <resolution>1</resolution>
                <min_angle>-1.47044</min_angle>
                <max_angle>1.47044</max_angle>
              </horizontal>
            </scan>
            <range>
              <min>0.01</min>
              <max>5</max>
              <resolution>0.01</resolution>
            </range>
          </lidar>
        </sensor>
      </link>
      <joint name='scan_front_joint' type='fixed'>
        <child>scan_front</child>
        <parent>base_link</parent>
      </joint>
      <link name='scan_back'>
        <pose>-0.2075 0 0.205 0 -0 -3.14159</pose>
        <sensor name='scan_back' type='gpu_lidar'>
          <update_rate>5</update_rate>
          <lidar>
            <scan>
              <horizontal>
                <samples>480</samples>
                <resolution>1</resolution>
                <min_angle>-1.47044</min_angle>
                <max_angle>1.47044</max_angle>
              </horizontal>
            </scan>
            <range>
              <min>0.01</min>
              <max>5</max>
              <resolution>0.01</resolution>
            </range>
          </lidar>
        </sensor>
      </link>
      <joint name='scan_back_joint' type='fixed'>
        <child>scan_back</child>
        <parent>base_link</parent>
      </joint>
      <link name='scan_omni'>
        <pose>-0.1855 0 0.5318 0 -0 0</pose>
        <visual name='velodyne_base'>
          <pose>0 0 -0.035 0 -0 0</pose>
          <geometry>
            <cylinder>
              <radius>0.06</radius>
              <length>0.0015</length>
            </cylinder>
          </geometry>
        </visual>
        <visual name='velodyne_suport_1'>
          <pose>-0.035 0.035 -0.08 0 -0 0</pose>
          <geometry>
            <cylinder>
              <radius>0.005</radius>
              <length>0.09</length>
            </cylinder>
          </geometry>
        </visual>
        <visual name='velodyne_suport_2'>
          <pose>-0.035 -0.035 -0.08 0 -0 0</pose>
          <geometry>
            <cylinder>
              <radius>0.005</radius>
              <length>0.09</length>
            </cylinder>
          </geometry>
        </visual>
        <visual name='velodyne_suport_3'>
          <pose>0.0495 0 -0.08 0 -0 0</pose>
          <geometry>
            <cylinder>
              <radius>0.005</radius>
              <length>0.09</length>
            </cylinder>
          </geometry>
        </visual>
        <visual name='velodyne_base_link_visual_base'>
          <pose>0 0 -0.035 0 -0 0</pose>
          <geometry>
            <mesh>
              <scale>1 1 1</scale>
              <uri>file:///home/truan/.ignition/fuel/fuel.ignitionrobotics.org/movai/models/tugbot/1/meshes/VLP16_base_1.dae</uri>
            </mesh>
          </geometry>
        </visual>
        <visual name='velodyne_base_link_visual_sensor'>
          <pose>0 0 -0.035 0 -0 0</pose>
          <geometry>
            <mesh>
              <scale>1 1 1</scale>
              <uri>file:///home/truan/.ignition/fuel/fuel.ignitionrobotics.org/movai/models/tugbot/1/meshes/VLP16_base_2.dae</uri>
            </mesh>
          </geometry>
        </visual>
        <visual name='base_link_velodyne_visual_scan'>
          <pose>0 0 -0.035 0 -0 0</pose>
          <geometry>
            <mesh>
              <scale>1 1 1</scale>
              <uri>file:///home/truan/.ignition/fuel/fuel.ignitionrobotics.org/movai/models/tugbot/1/meshes/VLP16_scan.dae</uri>
            </mesh>
          </geometry>
        </visual>
        <sensor name='scan_omni' type='gpu_lidar'>
          <update_rate>10</update_rate>
          <lidar>
            <scan>
              <horizontal>
                <samples>900</samples>
                <resolution>1</resolution>
                <min_angle>-3.14159</min_angle>
                <max_angle>3.14159</max_angle>
              </horizontal>
              <vertical>
                <samples>16</samples>
                <resolution>1</resolution>
                <min_angle>-0.261799</min_angle>
                <max_angle>0.261799</max_angle>
              </vertical>
            </scan>
            <range>
              <min>0.2</min>
              <max>100</max>
              <resolution>0.01</resolution>
            </range>
          </lidar>
        </sensor>
      </link>
      <joint name='scan_omni_joint' type='fixed'>
        <child>scan_omni</child>
        <parent>base_link</parent>
      </joint>
      <link name='gripper'>
        <pose>-0.35 0 0.1 0 -0 0</pose>
        <inertial>
          <pose>0 0 0 0 -0 0</pose>
          <mass>1</mass>
          <inertia>
            <ixx>0.00166667</ixx>
            <ixy>0</ixy>
            <ixz>0</ixz>
            <iyy>0.00166667</iyy>
            <iyz>0</iyz>
            <izz>0.00166667</izz>
          </inertia>
        </inertial>
        <collision name='gripper_collision'>
          <pose>-0.005 0 0 0 -0 0</pose>
          <max_contacts>5</max_contacts>
          <geometry>
            <box>
              <size>0.15 0.1 0.1</size>
            </box>
          </geometry>
          <surface>
            <contact>
              <ode>
                <kp>1e+06</kp>
                <kd>1</kd>
                <min_depth>0.01</min_depth>
                <max_vel>1</max_vel>
              </ode>
            </contact>
            <friction>
              <ode>
                <mu>1.16</mu>
                <mu2>1.16</mu2>
              </ode>
            </friction>
            <bounce/>
          </surface>
        </collision>
        <visual name='gripper_visual'>
          <pose>0 0 0 -1.5708 0 0</pose>
          <geometry>
            <mesh>
              <scale>1 1 1</scale>
              <uri>file:///home/truan/.ignition/fuel/fuel.ignitionrobotics.org/movai/models/tugbot/1/meshes/gripper2/gripper2.dae</uri>
            </mesh>
          </geometry>
        </visual>
        <sensor name='sensor_contact' type='gpu_lidar'>
          <pose>-0.075 0 0.035 0 -0 -3.14159</pose>
          <update_rate>10</update_rate>
          <lidar>
            <scan>
              <horizontal>
                <samples>3</samples>
                <resolution>1</resolution>
                <min_angle>-0.02</min_angle>
                <max_angle>0.02</max_angle>
              </horizontal>
            </scan>
            <range>
              <min>0.001</min>
              <max>0.01</max>
              <resolution>0.001</resolution>
            </range>
          </lidar>
        </sensor>
      </link>
      <joint name='gripper_joint' type='revolute'>
        <pose>0.35 0 0.09 0 -0 0</pose>
        <child>gripper</child>
        <parent>base_link</parent>
        <axis>
          <xyz>0 0 1</xyz>
          <limit>
            <lower>-0.7</lower>
            <upper>0.7</upper>
            <effort>4</effort>
            <velocity>0.5</velocity>
          </limit>
          <dynamics>
            <friction>0.5</friction>
            <spring_reference>0</spring_reference>
            <spring_stiffness>0</spring_stiffness>
          </dynamics>
        </axis>
      </joint>
      <link name='gripper_hand'>
        <pose>-0.463 0 0.1 0 -0 0</pose>
        <inertial>
          <pose>0 0 0 0 -0 0</pose>
          <mass>0.2</mass>
          <inertia>
            <ixx>1.6e-05</ixx>
            <ixy>0</ixy>
            <ixz>0</ixz>
            <iyy>1.6e-05</iyy>
            <iyz>0</iyz>
            <izz>1.6e-05</izz>
          </inertia>
        </inertial>
        <collision name='gripper_hand_collision'>
          <pose>0.015 0 0.006 0 -0 0</pose>
          <geometry>
            <box>
              <size>0.04 0.1 0.017</size>
            </box>
          </geometry>
          <max_contacts>5</max_contacts>
          <surface>
            <contact>
              <ode>
                <kp>1e+06</kp>
                <kd>1</kd>
                <min_depth>0.01</min_depth>
                <max_vel>1</max_vel>
              </ode>
            </contact>
            <friction>
              <ode>
                <mu>1.16</mu>
                <mu2>1.16</mu2>
              </ode>
            </friction>
            <bounce/>
          </surface>
        </collision>
        <visual name='gripper_hand_visual'>
          <pose>0 0 0 1.5708 -0 1.5708</pose>
          <geometry>
            <mesh>
              <scale>0.001 0.001 0.001</scale>
              <uri>file:///home/truan/.ignition/fuel/fuel.ignitionrobotics.org/movai/models/tugbot/1/meshes/gripper2/gripper_hand.stl</uri>
            </mesh>
          </geometry>
          <material>
            <ambient>0.1 0.1 0.1 1</ambient>
            <diffuse>0.3 0.3 0.3 1</diffuse>
            <specular>1 1 1 1</specular>
            <emissive>0 0 0 1</emissive>
          </material>
        </visual>
        <collision name='gripper_hand_sideL_collision'>
          <pose>0 0.08 0.03 0 -0 0</pose>
          <geometry>
            <box>
              <size>0.01 0.05 0.07</size>
            </box>
          </geometry>
          <surface>
            <contact>
              <ode>
                <kp>1e+06</kp>
                <kd>1</kd>
                <min_depth>0.01</min_depth>
                <max_vel>1</max_vel>
              </ode>
            </contact>
            <friction>
              <ode>
                <mu>1.16</mu>
                <mu2>1.16</mu2>
              </ode>
            </friction>
            <bounce/>
          </surface>
        </collision>
        <collision name='gripper_hand_sideL_slide_collision'>
          <pose>0 0.055 0.03 0.9 -0 0</pose>
          <geometry>
            <box>
              <size>0.01 0.055 0.04</size>
            </box>
          </geometry>
          <surface>
            <contact>
              <ode>
                <kp>1e+06</kp>
                <kd>1</kd>
                <min_depth>0.01</min_depth>
                <max_vel>1</max_vel>
              </ode>
            </contact>
            <friction>
              <ode>
                <mu>0</mu>
                <mu2>0</mu2>
              </ode>
            </friction>
            <bounce/>
          </surface>
        </collision>
        <collision name='gripper_hand_sideR_collision'>
          <pose>0 -0.08 0.03 0 -0 0</pose>
          <geometry>
            <box>
              <size>0.01 0.05 0.07</size>
            </box>
          </geometry>
          <surface>
            <contact>
              <ode>
                <kp>1e+06</kp>
                <kd>1</kd>
                <min_depth>0.01</min_depth>
                <max_vel>1</max_vel>
              </ode>
            </contact>
            <friction>
              <ode>
                <mu>1.16</mu>
                <mu2>1.16</mu2>
              </ode>
            </friction>
            <bounce/>
          </surface>
        </collision>
        <collision name='gripper_hand_sideR_slide_collision'>
          <pose>0 -0.055 0.03 -0.9 0 0</pose>
          <geometry>
            <box>
              <size>0.01 0.055 0.04</size>
            </box>
          </geometry>
          <surface>
            <contact>
              <ode>
                <kp>1e+06</kp>
                <kd>1</kd>
                <min_depth>0.01</min_depth>
                <max_vel>1</max_vel>
              </ode>
            </contact>
            <friction>
              <ode>
                <mu>0</mu>
                <mu2>0</mu2>
              </ode>
            </friction>
            <bounce/>
          </surface>
        </collision>
      </link>
      <joint name='gripper_hand_joint' type='revolute'>
        <pose>0.2 0 0 0 -0 0</pose>
        <child>gripper_hand</child>
        <parent>gripper</parent>
        <axis>
          <xyz>0 1 0</xyz>
          <limit>
            <lower>-0.35</lower>
            <upper>0.1</upper>
            <effort>100</effort>
            <velocity>0.5</velocity>
          </limit>
        </axis>
      </joint>
      <link name='wheel_front'>
        <pose>0.145 0 0.0345 1.5708 -0 0</pose>
        <inertial>
          <pose>0 0 0 0 -0 0</pose>
          <mass>0.1</mass>
          <inertia>
            <ixx>1.75e-05</ixx>
            <ixy>0</ixy>
            <ixz>0</ixz>
            <iyy>1.75e-05</iyy>
            <iyz>0</iyz>
            <izz>1.75e-05</izz>
          </inertia>
        </inertial>
        <collision name='wheel_front_collision'>
          <pose>0 0 0 0 -0 0</pose>
          <geometry>
            <sphere>
              <radius>0.025</radius>
            </sphere>
          </geometry>
          <max_contacts>2</max_contacts>
          <surface>
            <contact>
              <ode>
                <kp>1e+06</kp>
                <kd>1</kd>
                <min_depth>0.01</min_depth>
                <max_vel>1</max_vel>
              </ode>
            </contact>
            <friction>
              <ode>
                <mu>1.16</mu>
                <mu2>1.16</mu2>
              </ode>
            </friction>
            <bounce/>
          </surface>
        </collision>
      </link>
      <joint name='wheel_front_joint' type='ball'>
        <child>wheel_front</child>
        <parent>base_link</parent>
        <axis>
          <limit>
            <effort>100</effort>
            <lower>-1e+16</lower>
            <upper>1e+16</upper>
          </limit>
          <dynamics>
            <spring_reference>0</spring_reference>
            <spring_stiffness>0</spring_stiffness>
            <damping>10</damping>
          </dynamics>
          <xyz>0 0 1</xyz>
        </axis>
      </joint>
      <link name='wheel_back'>
        <pose>-0.225 0 0.035 1.5708 -0 0</pose>
        <inertial>
          <pose>0 0 0 0 -0 0</pose>
          <mass>0.1</mass>
          <inertia>
            <ixx>1.75e-05</ixx>
            <ixy>0</ixy>
            <ixz>0</ixz>
            <iyy>1.75e-05</iyy>
            <iyz>0</iyz>
            <izz>1.75e-05</izz>
          </inertia>
        </inertial>
        <collision name='wheel_back_collision'>
          <pose>0 0 0 0 -0 0</pose>
          <geometry>
            <sphere>
              <radius>0.035</radius>
            </sphere>
          </geometry>
          <max_contacts>2</max_contacts>
          <surface>
            <contact>
              <ode>
                <kp>1e+06</kp>
                <kd>1</kd>
                <min_depth>0.01</min_depth>
                <max_vel>1</max_vel>
              </ode>
            </contact>
            <friction>
              <ode>
                <mu>1.16</mu>
                <mu2>1.16</mu2>
              </ode>
            </friction>
            <bounce/>
          </surface>
        </collision>
      </link>
      <joint name='wheel_back_joint' type='ball'>
        <child>wheel_back</child>
        <parent>base_link</parent>
        <axis>
          <limit>
            <effort>100</effort>
            <lower>-1e+16</lower>
            <upper>1e+16</upper>
          </limit>
          <dynamics>
            <spring_reference>0</spring_reference>
            <spring_stiffness>0</spring_stiffness>
            <damping>10</damping>
          </dynamics>
          <xyz>0 0 1</xyz>
        </axis>
      </joint>
      <link name='wheel_left'>
        <pose>0 0.257 0.195 -1.5708 0 0</pose>
        <inertial>
          <pose>0 0 0 0 -0 0</pose>
          <mass>0.1</mass>
          <inertia>
            <ixx>1.75e-05</ixx>
            <ixy>0</ixy>
            <ixz>0</ixz>
            <iyy>1.75e-05</iyy>
            <iyz>0</iyz>
            <izz>3.125e-05</izz>
          </inertia>
        </inertial>
        <collision name='wheel_left_collision'>
          <pose>0 0 0 0 -0 0</pose>
          <geometry>
            <cylinder>
              <radius>0.195</radius>
              <length>0.05</length>
            </cylinder>
          </geometry>
          <max_contacts>5</max_contacts>
          <surface>
            <contact>
              <ode>
                <kp>1e+06</kp>
                <kd>1</kd>
                <min_depth>0.01</min_depth>
                <max_vel>1</max_vel>
              </ode>
            </contact>
            <friction>
              <ode>
                <mu>1.16</mu>
                <mu2>10</mu2>
                <fdir1>1 0 0</fdir1>
              </ode>
            </friction>
            <bounce/>
          </surface>
        </collision>
        <visual name='wheel_left_visual'>
          <pose>0 0 -0.03 0 -0 0</pose>
          <geometry>
            <mesh>
              <scale>0.98 0.98 1</scale>
              <uri>file:///home/truan/.ignition/fuel/fuel.ignitionrobotics.org/movai/models/tugbot/1/meshes/wheel/wheel.dae</uri>
            </mesh>
          </geometry>
        </visual>
      </link>
      <joint name='wheel_left_joint' type='revolute'>
        <child>wheel_left</child>
        <parent>base_link</parent>
        <axis>
          <xyz>0 0 1</xyz>
          <limit>
            <effort>9.6</effort>
            <lower>-1e+16</lower>
            <upper>1e+16</upper>
          </limit>
          <dynamics>
            <damping>3</damping>
            <friction>0.5</friction>
            <spring_reference>0</spring_reference>
            <spring_stiffness>0</spring_stiffness>
          </dynamics>
        </axis>
      </joint>
      <link name='wheel_right'>
        <pose>0 -0.257 0.195 1.5708 -0 0</pose>
        <inertial>
          <pose>0 0 0 0 -0 0</pose>
          <mass>0.1</mass>
          <inertia>
            <ixx>1.75e-05</ixx>
            <ixy>0</ixy>
            <ixz>0</ixz>
            <iyy>1.75e-05</iyy>
            <iyz>0</iyz>
            <izz>3.125e-05</izz>
          </inertia>
        </inertial>
        <collision name='wheel_right_collision'>
          <pose>0 0 0 0 -0 0</pose>
          <geometry>
            <cylinder>
              <radius>0.195</radius>
              <length>0.05</length>
            </cylinder>
          </geometry>
          <max_contacts>5</max_contacts>
          <surface>
            <contact>
              <ode>
                <kp>1e+06</kp>
                <kd>1</kd>
                <min_depth>0.01</min_depth>
                <max_vel>1</max_vel>
              </ode>
            </contact>
            <friction>
              <ode>
                <mu>1.16</mu>
                <mu2>10</mu2>
                <fdir1>1 0 0</fdir1>
              </ode>
            </friction>
            <bounce/>
          </surface>
        </collision>
        <visual name='wheel_right_visual'>
          <pose>0 0 -0.03 0 -0 0</pose>
          <geometry>
            <mesh>
              <scale>0.98 0.98 1</scale>
              <uri>file:///home/truan/.ignition/fuel/fuel.ignitionrobotics.org/movai/models/tugbot/1/meshes/wheel/wheel.dae</uri>
            </mesh>
          </geometry>
        </visual>
      </link>
      <joint name='wheel_right_joint' type='revolute'>
        <child>wheel_right</child>
        <parent>base_link</parent>
        <axis>
          <xyz>0 0 -1</xyz>
          <limit>
            <effort>9.6</effort>
            <lower>-1e+16</lower>
            <upper>1e+16</upper>
          </limit>
          <dynamics>
            <damping>3</damping>
            <friction>0.5</friction>
            <spring_reference>0</spring_reference>
            <spring_stiffness>0</spring_stiffness>
          </dynamics>
        </axis>
      </joint>
      <plugin name='ignition::gazebo::systems::DiffDrive' filename='ignition-gazebo-diff-drive-system'>
        <left_joint>wheel_left_joint</left_joint>
        <right_joint>wheel_right_joint</right_joint>
        <wheel_separation>0.5605</wheel_separation>
        <wheel_radius>0.195</wheel_radius>
        <odom_publish_frequency>20</odom_publish_frequency>
        <frame_id>odom</frame_id>
        <child_frame_id>base_link</child_frame_id>
      </plugin>
      <plugin name='ignition::gazebo::systems::JointController' filename='ignition-gazebo-joint-controller-system'>
        <joint_name>gripper_joint</joint_name>
        <use_force_commands>1</use_force_commands>
        <p_gain>0.2</p_gain>
        <i_gain>0.01</i_gain>
      </plugin>
      <plugin name='ignition::gazebo::systems::JointController' filename='ignition-gazebo-joint-controller-system'>
        <joint_name>gripper_hand_joint</joint_name>
        <use_force_commands>1</use_force_commands>
        <p_gain>0.2</p_gain>
        <i_gain>0.01</i_gain>
      </plugin>
      <plugin name='ignition::gazebo::systems::PosePublisher' filename='ignition-gazebo-pose-publisher-system'>
        <publish_link_pose>1</publish_link_pose>
        <publish_collision_pose>0</publish_collision_pose>
        <publish_visual_pose>0</publish_visual_pose>
        <publish_sensor_pose>0</publish_sensor_pose>
        <publish_nested_model_pose>1</publish_nested_model_pose>
        <update_frequency>20</update_frequency>
      </plugin>
      <plugin name='ignition::gazebo::systems::JointController' filename='ignition-gazebo-joint-controller-system'>
        <joint_name>warnign_light_joint</joint_name>
        <initial_velocity>10.0</initial_velocity>
      </plugin>
      <plugin name='ignition::gazebo::systems::LinearBatteryPlugin' filename='ignition-gazebo-linearbatteryplugin-system'>
        <battery_name>linear_battery</battery_name>
        <voltage>24.592</voltage>
        <open_circuit_voltage_constant_coef>24.592</open_circuit_voltage_constant_coef>
        <capacity>1.2009</capacity>
        <power_load>6.5</power_load>
        <fix_issue_225>1</fix_issue_225>
        <enable_recharge>1</enable_recharge>
        <charging_time>3.0</charging_time>
        <recharge_by_topic>1</recharge_by_topic>
      </plugin>
      <plugin name='ignition::gazebo::systems::JointStatePublisher' filename='ignition-gazebo-joint-state-publisher-system'>
        <joint_name>gripper_joint</joint_name>
        <joint_name>gripper_hand_joint</joint_name>
      </plugin>
    </model>
    <model name='cart1'>
      <pose>-5.73 15 0.25 0 -0 0</pose>
      <link name='base_link'>
        <pose>0 0 0 0 0 -1.5708</pose>
        <inertial>
          <pose>0 -0.5 0.5 0 -0 0</pose>
          <mass>30</mass>
          <inertia>
            <ixx>0.1</ixx>
            <ixy>0</ixy>
            <ixz>0</ixz>
            <iyy>0.1</iyy>
            <iyz>0</iyz>
            <izz>0.1</izz>
          </inertia>
        </inertial>
        <collision name='base_link_collision'>
          <pose>0 0 0 0 -0 0</pose>
          <geometry>
            <mesh>
              <scale>1 1 1</scale>
              <uri>file:///home/truan/.ignition/fuel/fuel.ignitionrobotics.org/movai/models/cart_model_2/2/meshes/cart_base_collision.stl</uri>
            </mesh>
          </geometry>
          <max_contacts>5</max_contacts>
          <surface>
            <contact>
              <ode>
                <soft_cfm>1</soft_cfm>
                <soft_erp>0.4</soft_erp>
                <kp>1e+06</kp>
                <kd>1</kd>
                <min_depth>0.01</min_depth>
              </ode>
            </contact>
            <friction>
              <ode>
                <mu>1.16</mu>
                <mu2>1.16</mu2>
              </ode>
            </friction>
          </surface>
        </collision>
        <visual name='base_link_visual'>
          <pose>0 0 0 0 -0 0</pose>
          <geometry>
            <mesh>
              <scale>1 1 1</scale>
              <uri>file:///home/truan/.ignition/fuel/fuel.ignitionrobotics.org/movai/models/cart_model_2/2/meshes/cart_base.dae</uri>
              <submesh>
                <name>base_metal</name>
                <center>0</center>
              </submesh>
            </mesh>
          </geometry>
        </visual>
        <visual name='base_shelf_visual'>
          <pose>0 0 0 0 -0 0</pose>
          <geometry>
            <mesh>
              <scale>1 1 1</scale>
              <uri>file:///home/truan/.ignition/fuel/fuel.ignitionrobotics.org/movai/models/cart_model_2/2/meshes/cart_base.dae</uri>
              <submesh>
                <name>base_shelf</name>
                <center>0</center>
              </submesh>
            </mesh>
          </geometry>
        </visual>
        <visual name='back_left_sup_visual'>
          <pose>-0.245 -1.005 0.05 0 -0 0</pose>
          <geometry>
            <mesh>
              <scale>1 1 1</scale>
              <uri>file:///home/truan/.ignition/fuel/fuel.ignitionrobotics.org/movai/models/cart_model_2/2/meshes/sup_wheels.dae</uri>
            </mesh>
          </geometry>
        </visual>
        <visual name='back_right_sup_visual'>
          <pose>0.245 -1.005 0.05 0 -0 0</pose>
          <geometry>
            <mesh>
              <scale>1 1 1</scale>
              <uri>file:///home/truan/.ignition/fuel/fuel.ignitionrobotics.org/movai/models/cart_model_2/2/meshes/sup_wheels.dae</uri>
            </mesh>
          </geometry>
        </visual>
        <visual name='tag_visual'>
          <pose>0 0 0 0 -0 0</pose>
          <geometry>
            <mesh>
              <scale>1 1 1</scale>
              <uri>file:///home/truan/.ignition/fuel/fuel.ignitionrobotics.org/movai/models/cart_model_2/2/meshes/cart_base.dae</uri>
              <submesh>
                <name>tag</name>
                <center>0</center>
              </submesh>
            </mesh>
          </geometry>
          <material>
            <diffuse>1 1 1 1</diffuse>
            <specular>1 1 1 1</specular>
            <pbr>
              <metal>
                <albedo_map>meshes/cart_tag.png</albedo_map>
              </metal>
            </pbr>
          </material>
        </visual>
      </link>
      <link name='back_left'>
        <pose>-1.04 -0.245 -0.05 0 -0 1.5708</pose>
        <inertial>
          <pose>0 0 0 0 1.5708 0</pose>
          <mass>0.01</mass>
          <inertia>
            <ixx>1.75e-05</ixx>
            <ixy>0</ixy>
            <ixz>0</ixz>
            <iyy>1.75e-05</iyy>
            <iyz>0</iyz>
            <izz>3.125e-05</izz>
          </inertia>
        </inertial>
        <collision name='back_left_collision'>
          <pose>0 0 0 0 1.5708 0</pose>
          <geometry>
            <cylinder>
              <length>0.03</length>
              <radius>0.06</radius>
            </cylinder>
          </geometry>
          <max_contacts>5</max_contacts>
          <surface>
            <contact>
              <ode>
                <soft_cfm>1</soft_cfm>
                <soft_erp>0.4</soft_erp>
                <kp>1e+06</kp>
                <kd>1</kd>
                <min_depth>0.01</min_depth>
              </ode>
            </contact>
            <friction>
              <ode>
                <mu>1.16</mu>
                <mu2>1.16</mu2>
              </ode>
            </friction>
            <bounce/>
          </surface>
        </collision>
        <visual name='back_left_visual'>
          <pose>0 0 0 0 -0 0</pose>
          <geometry>
            <mesh>
              <scale>1 1 1</scale>
              <uri>file:///home/truan/.ignition/fuel/fuel.ignitionrobotics.org/movai/models/cart_model_2/2/meshes/wheel.dae</uri>
            </mesh>
          </geometry>
        </visual>
      </link>
      <joint name='back_left_joint' type='revolute'>
        <child>back_left</child>
        <parent>base_link</parent>
        <axis>
          <xyz>1 0 0</xyz>
          <dynamics>
            <friction>0.5</friction>
            <damping>0.0001</damping>
            <spring_reference>0</spring_reference>
            <spring_stiffness>0</spring_stiffness>
          </dynamics>
          <limit>
            <lower>-1e+16</lower>
            <upper>1e+16</upper>
          </limit>
        </axis>
      </joint>
      <link name='back_right'>
        <pose>-1.04 0.245 -0.05 0 -0 1.5708</pose>
        <inertial>
          <pose>0 0 0 0 1.5708 0</pose>
          <mass>0.01</mass>
          <inertia>
            <ixx>1.75e-05</ixx>
            <ixy>0</ixy>
            <ixz>0</ixz>
            <iyy>1.75e-05</iyy>
            <iyz>0</iyz>
            <izz>3.125e-05</izz>
          </inertia>
        </inertial>
        <collision name='back_right_collision'>
          <pose>0 0 0 0 1.5708 0</pose>
          <geometry>
            <cylinder>
              <length>0.03</length>
              <radius>0.06</radius>
            </cylinder>
          </geometry>
          <max_contacts>5</max_contacts>
          <surface>
            <contact>
              <ode>
                <soft_cfm>1</soft_cfm>
                <soft_erp>0.4</soft_erp>
                <kp>1e+06</kp>
                <kd>1</kd>
                <min_depth>0.01</min_depth>
              </ode>
            </contact>
            <friction>
              <ode>
                <mu>1.16</mu>
                <mu2>1.16</mu2>
              </ode>
            </friction>
            <bounce/>
          </surface>
        </collision>
        <visual name='back_right_visual'>
          <pose>0 0 0 0 -0 0</pose>
          <geometry>
            <mesh>
              <scale>1 1 1</scale>
              <uri>file:///home/truan/.ignition/fuel/fuel.ignitionrobotics.org/movai/models/cart_model_2/2/meshes/wheel.dae</uri>
            </mesh>
          </geometry>
        </visual>
      </link>
      <joint name='back_right_joint' type='revolute'>
        <child>back_right</child>
        <parent>base_link</parent>
        <axis>
          <xyz>1 0 0</xyz>
          <dynamics>
            <friction>0.5</friction>
            <damping>0.0001</damping>
            <spring_reference>0</spring_reference>
            <spring_stiffness>0</spring_stiffness>
          </dynamics>
          <limit>
            <lower>-1e+16</lower>
            <upper>1e+16</upper>
          </limit>
        </axis>
      </joint>
      <link name='wheel_sup_front_left'>
        <pose>0 -0.245 0.05 0 -0 1.5708</pose>
        <inertial>
          <pose>0 0 0 0 -0 0</pose>
          <mass>0.01</mass>
          <inertia>
            <ixx>1.75e-05</ixx>
            <ixy>0</ixy>
            <ixz>0</ixz>
            <iyy>1.75e-05</iyy>
            <iyz>0</iyz>
            <izz>1.75e-05</izz>
          </inertia>
        </inertial>
        <visual name='wheel_sup_front_left_visual'>
          <pose>0 0 0 0 -0 -3.14159</pose>
          <geometry>
            <mesh>
              <scale>1 1 1</scale>
              <uri>file:///home/truan/.ignition/fuel/fuel.ignitionrobotics.org/movai/models/cart_model_2/2/meshes/sup_wheels.dae</uri>
            </mesh>
          </geometry>
        </visual>
      </link>
      <joint name='wheel_sup_front_left_joint' type='revolute'>
        <child>wheel_sup_front_left</child>
        <parent>base_link</parent>
        <axis>
          <xyz>0 0 1</xyz>
          <dynamics>
            <damping>0.001</damping>
            <spring_reference>0</spring_reference>
            <spring_stiffness>0</spring_stiffness>
          </dynamics>
          <limit>
            <lower>-1e+16</lower>
            <upper>1e+16</upper>
          </limit>
        </axis>
      </joint>
      <link name='front_left'>
        <pose>-0.04 -0.245 -0.05 0 -0 1.5708</pose>
        <inertial>
          <pose>0 0 0 0 1.5708 0</pose>
          <mass>0.01</mass>
          <inertia>
            <ixx>1.75e-05</ixx>
            <ixy>0</ixy>
            <ixz>0</ixz>
            <iyy>1.75e-05</iyy>
            <iyz>0</iyz>
            <izz>3.125e-05</izz>
          </inertia>
        </inertial>
        <collision name='front_left_collision'>
          <pose>0 0 0 0 1.5708 0</pose>
          <geometry>
            <cylinder>
              <length>0.03</length>
              <radius>0.06</radius>
            </cylinder>
          </geometry>
          <max_contacts>5</max_contacts>
          <surface>
            <contact>
              <ode>
                <soft_cfm>1</soft_cfm>
                <soft_erp>0.4</soft_erp>
                <kp>1e+06</kp>
                <kd>1</kd>
                <min_depth>0.01</min_depth>
              </ode>
            </contact>
            <friction>
              <ode>
                <mu>1.16</mu>
                <mu2>1.16</mu2>
              </ode>
            </friction>
            <bounce/>
          </surface>
        </collision>
        <visual name='front_left_visual'>
          <pose>0 0 0 0 -0 0</pose>
          <geometry>
            <mesh>
              <scale>1 1 1</scale>
              <uri>file:///home/truan/.ignition/fuel/fuel.ignitionrobotics.org/movai/models/cart_model_2/2/meshes/wheel.dae</uri>
            </mesh>
          </geometry>
        </visual>
      </link>
      <joint name='front_left_joint' type='revolute'>
        <child>front_left</child>
        <parent>wheel_sup_front_left</parent>
        <axis>
          <xyz>1 0 0</xyz>
          <dynamics>
            <friction>0.5</friction>
            <damping>0.0001</damping>
            <spring_reference>0</spring_reference>
            <spring_stiffness>0</spring_stiffness>
          </dynamics>
          <limit>
            <lower>-1e+16</lower>
            <upper>1e+16</upper>
          </limit>
        </axis>
      </joint>
      <link name='wheel_sup_front_right'>
        <pose>0 0.245 0.05 0 -0 1.5708</pose>
        <inertial>
          <pose>0 0 0 0 -0 0</pose>
          <mass>0.01</mass>
          <inertia>
            <ixx>1.75e-05</ixx>
            <ixy>0</ixy>
            <ixz>0</ixz>
            <iyy>1.75e-05</iyy>
            <iyz>0</iyz>
            <izz>1.75e-05</izz>
          </inertia>
        </inertial>
        <visual name='wheel_sup_front_right_visual'>
          <pose>0 0 0 0 -0 -3.14159</pose>
          <geometry>
            <mesh>
              <scale>1 1 1</scale>
              <uri>file:///home/truan/.ignition/fuel/fuel.ignitionrobotics.org/movai/models/cart_model_2/2/meshes/sup_wheels.dae</uri>
            </mesh>
          </geometry>
        </visual>
      </link>
      <joint name='wheel_sup_front_right_joint' type='revolute'>
        <child>wheel_sup_front_right</child>
        <parent>base_link</parent>
        <axis>
          <xyz>0 0 1</xyz>
          <dynamics>
            <damping>0.001</damping>
            <spring_reference>0</spring_reference>
            <spring_stiffness>0</spring_stiffness>
          </dynamics>
          <limit>
            <lower>-1e+16</lower>
            <upper>1e+16</upper>
          </limit>
        </axis>
      </joint>
      <link name='front_right'>
        <pose>-0.04 0.245 -0.05 0 -0 1.5708</pose>
        <inertial>
          <pose>0 0 0 0 1.5708 0</pose>
          <mass>0.01</mass>
          <inertia>
            <ixx>1.75e-05</ixx>
            <ixy>0</ixy>
            <ixz>0</ixz>
            <iyy>1.75e-05</iyy>
            <iyz>0</iyz>
            <izz>3.125e-05</izz>
          </inertia>
        </inertial>
        <collision name='front_right_collision'>
          <pose>0 0 0 0 1.5708 0</pose>
          <geometry>
            <cylinder>
              <length>0.03</length>
              <radius>0.06</radius>
            </cylinder>
          </geometry>
          <max_contacts>5</max_contacts>
          <surface>
            <contact>
              <ode>
                <soft_cfm>1</soft_cfm>
                <soft_erp>0.4</soft_erp>
                <kp>1e+06</kp>
                <kd>1</kd>
                <min_depth>0.01</min_depth>
              </ode>
            </contact>
            <friction>
              <ode>
                <mu>1.16</mu>
                <mu2>1.16</mu2>
              </ode>
            </friction>
            <bounce/>
          </surface>
        </collision>
        <visual name='front_right_visual'>
          <pose>0 0 0 0 -0 0</pose>
          <geometry>
            <mesh>
              <scale>1 1 1</scale>
              <uri>file:///home/truan/.ignition/fuel/fuel.ignitionrobotics.org/movai/models/cart_model_2/2/meshes/wheel.dae</uri>
            </mesh>
          </geometry>
        </visual>
      </link>
      <joint name='front_right_joint' type='revolute'>
        <child>front_right</child>
        <parent>wheel_sup_front_right</parent>
        <axis>
          <xyz>1 0 0</xyz>
          <dynamics>
            <friction>0.5</friction>
            <damping>0.0001</damping>
            <spring_reference>0</spring_reference>
            <spring_stiffness>0</spring_stiffness>
          </dynamics>
          <limit>
            <lower>-1e+16</lower>
            <upper>1e+16</upper>
          </limit>
        </axis>
      </joint>
    </model>
    <model name='shelf_big_0'>
      <pose>-9.34177 -13.5598 0 0 -0 0</pose>
      <self_collide>1</self_collide>
      <link name='shelf_big_base'>
        <pose>-0.5 0 0 0 -0 0</pose>
        <collision name='shelf_big_chassi_collision'>
          <pose>0 0 3 0 -0 0</pose>
          <geometry>
            <box>
              <size>2.1 18 6</size>
            </box>
          </geometry>
          <surface>
            <friction>
              <ode/>
            </friction>
            <bounce/>
            <contact/>
          </surface>
        </collision>
        <visual name='shelf_big_chassi_visual'>
          <pose>0 0 0 0 -0 1.5708</pose>
          <geometry>
            <mesh>
              <scale>1 1 1</scale>
              <uri>file:///home/truan/.ignition/fuel/fuel.ignitionrobotics.org/movai/models/shelf_big/2/meshes/shelf_big_movai.dae</uri>
            </mesh>
          </geometry>
        </visual>
      </link>
      <static>1</static>
    </model>
    <model name='shelf'>
      <pose>-4.41528 -0.690987 0 0 -0 0</pose>
      <self_collide>1</self_collide>
      <link name='shelf_base'>
        <pose>-0.5 0 0 0 -0 0</pose>
        <collision name='shelf_chassi_collision'>
          <pose>0 0 0.9 0 -0 0</pose>
          <geometry>
            <box>
              <size>3.6 0.6 1.8</size>
            </box>
          </geometry>
          <surface>
            <friction>
              <ode/>
            </friction>
            <bounce/>
            <contact/>
          </surface>
        </collision>
        <visual name='shelf_chassi_visual'>
          <pose>0 0 0 0 -0 0</pose>
          <geometry>
            <mesh>
              <scale>0.2 0.3 0.3</scale>
              <uri>file:///home/truan/.ignition/fuel/fuel.ignitionrobotics.org/movai/models/shelf/1/meshes/shelf_big_movai.dae</uri>
            </mesh>
          </geometry>
        </visual>
      </link>
      <static>1</static>
    </model>
    <model name='shelf_0'>
      <pose>-4.41528 2.30697 0 0 -0 0</pose>
      <self_collide>1</self_collide>
      <link name='shelf_base'>
        <pose>-0.5 0 0 0 -0 0</pose>
        <collision name='shelf_chassi_collision'>
          <pose>0 0 0.9 0 -0 0</pose>
          <geometry>
            <box>
              <size>3.6 0.6 1.8</size>
            </box>
          </geometry>
          <surface>
            <friction>
              <ode/>
            </friction>
            <bounce/>
            <contact/>
          </surface>
        </collision>
        <visual name='shelf_chassi_visual'>
          <pose>0 0 0 0 -0 0</pose>
          <geometry>
            <mesh>
              <scale>0.2 0.3 0.3</scale>
              <uri>file:///home/truan/.ignition/fuel/fuel.ignitionrobotics.org/movai/models/shelf/1/meshes/shelf_big_movai.dae</uri>
            </mesh>
          </geometry>
        </visual>
      </link>
      <static>1</static>
    </model>
    <model name='shelf_1'>
      <pose>-4.41528 5.30708 0 0 -0 0</pose>
      <self_collide>1</self_collide>
      <link name='shelf_base'>
        <pose>-0.5 0 0 0 -0 0</pose>
        <collision name='shelf_chassi_collision'>
          <pose>0 0 0.9 0 -0 0</pose>
          <geometry>
            <box>
              <size>3.6 0.6 1.8</size>
            </box>
          </geometry>
          <surface>
            <friction>
              <ode/>
            </friction>
            <bounce/>
            <contact/>
          </surface>
        </collision>
        <visual name='shelf_chassi_visual'>
          <pose>0 0 0 0 -0 0</pose>
          <geometry>
            <mesh>
              <scale>0.2 0.3 0.3</scale>
              <uri>file:///home/truan/.ignition/fuel/fuel.ignitionrobotics.org/movai/models/shelf/1/meshes/shelf_big_movai.dae</uri>
            </mesh>
          </geometry>
        </visual>
      </link>
      <static>1</static>
    </model>
    <model name='shelf_2'>
      <pose>-4.41528 8.34352 0 0 -0 0</pose>
      <self_collide>1</self_collide>
      <link name='shelf_base'>
        <pose>-0.5 0 0 0 -0 0</pose>
        <collision name='shelf_chassi_collision'>
          <pose>0 0 0.9 0 -0 0</pose>
          <geometry>
            <box>
              <size>3.6 0.6 1.8</size>
            </box>
          </geometry>
          <surface>
            <friction>
              <ode/>
            </friction>
            <bounce/>
            <contact/>
          </surface>
        </collision>
        <visual name='shelf_chassi_visual'>
          <pose>0 0 0 0 -0 0</pose>
          <geometry>
            <mesh>
              <scale>0.2 0.3 0.3</scale>
              <uri>file:///home/truan/.ignition/fuel/fuel.ignitionrobotics.org/movai/models/shelf/1/meshes/shelf_big_movai.dae</uri>
            </mesh>
          </geometry>
        </visual>
      </link>
      <static>1</static>
    </model>
    <model name='shelf_3'>
      <pose>5.60144 8.34352 0 0 -0 0</pose>
      <self_collide>1</self_collide>
      <link name='shelf_base'>
        <pose>-0.5 0 0 0 -0 0</pose>
        <collision name='shelf_chassi_collision'>
          <pose>0 0 0.9 0 -0 0</pose>
          <geometry>
            <box>
              <size>3.6 0.6 1.8</size>
            </box>
          </geometry>
          <surface>
            <friction>
              <ode/>
            </friction>
            <bounce/>
            <contact/>
          </surface>
        </collision>
        <visual name='shelf_chassi_visual'>
          <pose>0 0 0 0 -0 0</pose>
          <geometry>
            <mesh>
              <scale>0.2 0.3 0.3</scale>
              <uri>file:///home/truan/.ignition/fuel/fuel.ignitionrobotics.org/movai/models/shelf/1/meshes/shelf_big_movai.dae</uri>
            </mesh>
          </geometry>
        </visual>
      </link>
      <static>1</static>
    </model>
    <model name='shelf_4'>
      <pose>5.60144 5.30708 0 0 -0 0</pose>
      <self_collide>1</self_collide>
      <link name='shelf_base'>
        <pose>-0.5 0 0 0 -0 0</pose>
        <collision name='shelf_chassi_collision'>
          <pose>0 0 0.9 0 -0 0</pose>
          <geometry>
            <box>
              <size>3.6 0.6 1.8</size>
            </box>
          </geometry>
          <surface>
            <friction>
              <ode/>
            </friction>
            <bounce/>
            <contact/>
          </surface>
        </collision>
        <visual name='shelf_chassi_visual'>
          <pose>0 0 0 0 -0 0</pose>
          <geometry>
            <mesh>
              <scale>0.2 0.3 0.3</scale>
              <uri>file:///home/truan/.ignition/fuel/fuel.ignitionrobotics.org/movai/models/shelf/1/meshes/shelf_big_movai.dae</uri>
            </mesh>
          </geometry>
        </visual>
      </link>
      <static>1</static>
    </model>
    <model name='shelf_5'>
      <pose>5.60144 -0.690987 0 0 -0 0</pose>
      <self_collide>1</self_collide>
      <link name='shelf_base'>
        <pose>-0.5 0 0 0 -0 0</pose>
        <collision name='shelf_chassi_collision'>
          <pose>0 0 0.9 0 -0 0</pose>
          <geometry>
            <box>
              <size>3.6 0.6 1.8</size>
            </box>
          </geometry>
          <surface>
            <friction>
              <ode/>
            </friction>
            <bounce/>
            <contact/>
          </surface>
        </collision>
        <visual name='shelf_chassi_visual'>
          <pose>0 0 0 0 -0 0</pose>
          <geometry>
            <mesh>
              <scale>0.2 0.3 0.3</scale>
              <uri>file:///home/truan/.ignition/fuel/fuel.ignitionrobotics.org/movai/models/shelf/1/meshes/shelf_big_movai.dae</uri>
            </mesh>
          </geometry>
        </visual>
      </link>
      <static>1</static>
    </model>
    <model name='shelf_6'>
      <pose>5.60144 2.30697 0 0 -0 0</pose>
      <self_collide>1</self_collide>
      <link name='shelf_base'>
        <pose>-0.5 0 0 0 -0 0</pose>
        <collision name='shelf_chassi_collision'>
          <pose>0 0 0.9 0 -0 0</pose>
          <geometry>
            <box>
              <size>3.6 0.6 1.8</size>
            </box>
          </geometry>
          <surface>
            <friction>
              <ode/>
            </friction>
            <bounce/>
            <contact/>
          </surface>
        </collision>
        <visual name='shelf_chassi_visual'>
          <pose>0 0 0 0 -0 0</pose>
          <geometry>
            <mesh>
              <scale>0.2 0.3 0.3</scale>
              <uri>file:///home/truan/.ignition/fuel/fuel.ignitionrobotics.org/movai/models/shelf/1/meshes/shelf_big_movai.dae</uri>
            </mesh>
          </geometry>
        </visual>
      </link>
      <static>1</static>
    </model>
    <model name='pallet_box_mobile'>
      <pose>4.4161 14.6952 0.01 0 -0 0</pose>
      <self_collide>0</self_collide>
      <link name='pallet_base'>
        <pose>0 0 0 0 -0 0</pose>
        <inertial>
          <pose>0 0 0.4 0 -0 0</pose>
          <mass>200</mass>
          <inertia>
            <ixx>0.1</ixx>
            <ixy>0</ixy>
            <ixz>0</ixz>
            <iyy>0.1</iyy>
            <iyz>0</iyz>
            <izz>0.1</izz>
          </inertia>
        </inertial>
        <collision name='pallet_top_collision'>
          <pose>0 0 0.125 0 -0 0</pose>
          <geometry>
            <box>
              <size>1.22 0.8 0.04</size>
            </box>
          </geometry>
          <surface>
            <friction>
              <ode>
                <mu>0.4</mu>
                <mu2>0.4</mu2>
              </ode>
            </friction>
            <bounce/>
            <contact/>
          </surface>
        </collision>
        <collision name='pallet_center_collision'>
          <pose>0 0 0.055 0 -0 0</pose>
          <geometry>
            <box>
              <size>1.22 0.1 0.1</size>
            </box>
          </geometry>
          <surface>
            <friction>
              <ode/>
            </friction>
            <bounce/>
            <contact/>
          </surface>
        </collision>
        <collision name='pallet_left_collision'>
          <pose>0 -0.35 0.055 0 -0 0</pose>
          <geometry>
            <box>
              <size>1.22 0.1 0.1</size>
            </box>
          </geometry>
          <surface>
            <friction>
              <ode/>
            </friction>
            <bounce/>
            <contact/>
          </surface>
        </collision>
        <collision name='pallet_right_collision'>
          <pose>0 0.35 0.055 0 -0 0</pose>
          <geometry>
            <box>
              <size>1.22 0.1 0.1</size>
            </box>
          </geometry>
          <surface>
            <friction>
              <ode/>
            </friction>
            <bounce/>
            <contact/>
          </surface>
        </collision>
        <collision name='boxes_collision'>
          <pose>0 0 0.644 0 -0 0</pose>
          <geometry>
            <box>
              <size>1.22 0.8 1</size>
            </box>
          </geometry>
          <surface>
            <friction>
              <ode/>
            </friction>
            <bounce/>
            <contact/>
          </surface>
        </collision>
        <visual name='pallet_visual'>
          <pose>0 0 0 0 -0 0</pose>
          <geometry>
            <mesh>
              <scale>1 1 1</scale>
              <uri>https://fuel.ignitionrobotics.org/1.0/MovAi/models/pallet/tip/files/meshes/pallet.dae</uri>
            </mesh>
          </geometry>
        </visual>
        <visual name='boxes_visual'>
          <pose>-0.053875 0 0 0 -0 0</pose>
          <geometry>
            <mesh>
              <scale>1 1 1</scale>
              <uri>https://fuel.ignitionrobotics.org/1.0/movai/models/pallet_box_mobile/3/files/meshes/boxes.dae</uri>
            </mesh>
          </geometry>
        </visual>
      </link>
      <plugin name='ignition::gazebo::systems::PosePublisher' filename='ignition-gazebo-pose-publisher-system'>
        <publish_link_pose>1</publish_link_pose>
        <publish_collision_pose>0</publish_collision_pose>
        <publish_visual_pose>0</publish_visual_pose>
        <publish_nested_model_pose>1</publish_nested_model_pose>
        <update_frequency>20</update_frequency>
      </plugin>
      <static>0</static>
    </model>
    <model name='pallet_box_mobile_0'>
      <pose>4.45415 13.6212 0.01 0 -0 0</pose>
      <self_collide>0</self_collide>
      <link name='pallet_base'>
        <pose>0 0 0 0 -0 0</pose>
        <inertial>
          <pose>0 0 0.4 0 -0 0</pose>
          <mass>200</mass>
          <inertia>
            <ixx>0.1</ixx>
            <ixy>0</ixy>
            <ixz>0</ixz>
            <iyy>0.1</iyy>
            <iyz>0</iyz>
            <izz>0.1</izz>
          </inertia>
        </inertial>
        <collision name='pallet_top_collision'>
          <pose>0 0 0.125 0 -0 0</pose>
          <geometry>
            <box>
              <size>1.22 0.8 0.04</size>
            </box>
          </geometry>
          <surface>
            <friction>
              <ode>
                <mu>0.4</mu>
                <mu2>0.4</mu2>
              </ode>
            </friction>
            <bounce/>
            <contact/>
          </surface>
        </collision>
        <collision name='pallet_center_collision'>
          <pose>0 0 0.055 0 -0 0</pose>
          <geometry>
            <box>
              <size>1.22 0.1 0.1</size>
            </box>
          </geometry>
          <surface>
            <friction>
              <ode/>
            </friction>
            <bounce/>
            <contact/>
          </surface>
        </collision>
        <collision name='pallet_left_collision'>
          <pose>0 -0.35 0.055 0 -0 0</pose>
          <geometry>
            <box>
              <size>1.22 0.1 0.1</size>
            </box>
          </geometry>
          <surface>
            <friction>
              <ode/>
            </friction>
            <bounce/>
            <contact/>
          </surface>
        </collision>
        <collision name='pallet_right_collision'>
          <pose>0 0.35 0.055 0 -0 0</pose>
          <geometry>
            <box>
              <size>1.22 0.1 0.1</size>
            </box>
          </geometry>
          <surface>
            <friction>
              <ode/>
            </friction>
            <bounce/>
            <contact/>
          </surface>
        </collision>
        <collision name='boxes_collision'>
          <pose>0 0 0.644 0 -0 0</pose>
          <geometry>
            <box>
              <size>1.22 0.8 1</size>
            </box>
          </geometry>
          <surface>
            <friction>
              <ode/>
            </friction>
            <bounce/>
            <contact/>
          </surface>
        </collision>
        <visual name='pallet_visual'>
          <pose>0 0 0 0 -0 0</pose>
          <geometry>
            <mesh>
              <scale>1 1 1</scale>
              <uri>https://fuel.ignitionrobotics.org/1.0/MovAi/models/pallet/tip/files/meshes/pallet.dae</uri>
            </mesh>
          </geometry>
        </visual>
        <visual name='boxes_visual'>
          <pose>-0.053875 0 0 0 -0 0</pose>
          <geometry>
            <mesh>
              <scale>1 1 1</scale>
              <uri>https://fuel.ignitionrobotics.org/1.0/movai/models/pallet_box_mobile/3/files/meshes/boxes.dae</uri>
            </mesh>
          </geometry>
        </visual>
      </link>
      <plugin name='ignition::gazebo::systems::PosePublisher' filename='ignition-gazebo-pose-publisher-system'>
        <publish_link_pose>1</publish_link_pose>
        <publish_collision_pose>0</publish_collision_pose>
        <publish_visual_pose>0</publish_visual_pose>
        <publish_nested_model_pose>1</publish_nested_model_pose>
        <update_frequency>20</update_frequency>
      </plugin>
      <static>0</static>
    </model>
    <model name='pallet_box_mobile_1'>
      <pose>4.4468 12.229 0.01 0 -0 0</pose>
      <self_collide>0</self_collide>
      <link name='pallet_base'>
        <pose>0 0 0 0 -0 0</pose>
        <inertial>
          <pose>0 0 0.4 0 -0 0</pose>
          <mass>200</mass>
          <inertia>
            <ixx>0.1</ixx>
            <ixy>0</ixy>
            <ixz>0</ixz>
            <iyy>0.1</iyy>
            <iyz>0</iyz>
            <izz>0.1</izz>
          </inertia>
        </inertial>
        <collision name='pallet_top_collision'>
          <pose>0 0 0.125 0 -0 0</pose>
          <geometry>
            <box>
              <size>1.22 0.8 0.04</size>
            </box>
          </geometry>
          <surface>
            <friction>
              <ode>
                <mu>0.4</mu>
                <mu2>0.4</mu2>
              </ode>
            </friction>
            <bounce/>
            <contact/>
          </surface>
        </collision>
        <collision name='pallet_center_collision'>
          <pose>0 0 0.055 0 -0 0</pose>
          <geometry>
            <box>
              <size>1.22 0.1 0.1</size>
            </box>
          </geometry>
          <surface>
            <friction>
              <ode/>
            </friction>
            <bounce/>
            <contact/>
          </surface>
        </collision>
        <collision name='pallet_left_collision'>
          <pose>0 -0.35 0.055 0 -0 0</pose>
          <geometry>
            <box>
              <size>1.22 0.1 0.1</size>
            </box>
          </geometry>
          <surface>
            <friction>
              <ode/>
            </friction>
            <bounce/>
            <contact/>
          </surface>
        </collision>
        <collision name='pallet_right_collision'>
          <pose>0 0.35 0.055 0 -0 0</pose>
          <geometry>
            <box>
              <size>1.22 0.1 0.1</size>
            </box>
          </geometry>
          <surface>
            <friction>
              <ode/>
            </friction>
            <bounce/>
            <contact/>
          </surface>
        </collision>
        <collision name='boxes_collision'>
          <pose>0 0 0.644 0 -0 0</pose>
          <geometry>
            <box>
              <size>1.22 0.8 1</size>
            </box>
          </geometry>
          <surface>
            <friction>
              <ode/>
            </friction>
            <bounce/>
            <contact/>
          </surface>
        </collision>
        <visual name='pallet_visual'>
          <pose>0 0 0 0 -0 0</pose>
          <geometry>
            <mesh>
              <scale>1 1 1</scale>
              <uri>https://fuel.ignitionrobotics.org/1.0/MovAi/models/pallet/tip/files/meshes/pallet.dae</uri>
            </mesh>
          </geometry>
        </visual>
        <visual name='boxes_visual'>
          <pose>-0.053875 0 0 0 -0 0</pose>
          <geometry>
            <mesh>
              <scale>1 1 1</scale>
              <uri>https://fuel.ignitionrobotics.org/1.0/movai/models/pallet_box_mobile/3/files/meshes/boxes.dae</uri>
            </mesh>
          </geometry>
        </visual>
      </link>
      <plugin name='ignition::gazebo::systems::PosePublisher' filename='ignition-gazebo-pose-publisher-system'>
        <publish_link_pose>1</publish_link_pose>
        <publish_collision_pose>0</publish_collision_pose>
        <publish_visual_pose>0</publish_visual_pose>
        <publish_nested_model_pose>1</publish_nested_model_pose>
        <update_frequency>20</update_frequency>
      </plugin>
      <static>0</static>
    </model>
    <model name='pallet_box'>
      <pose>-6.11913 13.7079 0.01 0 -0 0</pose>
      <self_collide>0</self_collide>
      <link name='pallet_base'>
        <pose>0 0 0 0 -0 0</pose>
        <inertial>
          <pose>0 0 0.4 0 -0 0</pose>
          <mass>200</mass>
          <inertia>
            <ixx>0.1</ixx>
            <ixy>0</ixy>
            <ixz>0</ixz>
            <iyy>0.1</iyy>
            <iyz>0</iyz>
            <izz>0.1</izz>
          </inertia>
        </inertial>
        <collision name='pallet_top_collision'>
          <pose>0 0 0.125 0 -0 0</pose>
          <geometry>
            <box>
              <size>1.22 0.8 0.04</size>
            </box>
          </geometry>
          <surface>
            <friction>
              <ode>
                <mu>0.4</mu>
                <mu2>0.4</mu2>
              </ode>
            </friction>
            <bounce/>
            <contact/>
          </surface>
        </collision>
        <collision name='pallet_center_collision'>
          <pose>0 0 0.055 0 -0 0</pose>
          <geometry>
            <box>
              <size>1.22 0.1 0.1</size>
            </box>
          </geometry>
          <surface>
            <friction>
              <ode/>
            </friction>
            <bounce/>
            <contact/>
          </surface>
        </collision>
        <collision name='pallet_left_collision'>
          <pose>0 -0.35 0.055 0 -0 0</pose>
          <geometry>
            <box>
              <size>1.22 0.1 0.1</size>
            </box>
          </geometry>
          <surface>
            <friction>
              <ode/>
            </friction>
            <bounce/>
            <contact/>
          </surface>
        </collision>
        <collision name='pallet_right_collision'>
          <pose>0 0.35 0.055 0 -0 0</pose>
          <geometry>
            <box>
              <size>1.22 0.1 0.1</size>
            </box>
          </geometry>
          <surface>
            <friction>
              <ode/>
            </friction>
            <bounce/>
            <contact/>
          </surface>
        </collision>
        <collision name='boxes_collision'>
          <pose>0 0 0.644 0 -0 0</pose>
          <geometry>
            <box>
              <size>1.22 0.8 1</size>
            </box>
          </geometry>
          <surface>
            <friction>
              <ode/>
            </friction>
            <bounce/>
            <contact/>
          </surface>
        </collision>
        <visual name='pallet_visual'>
          <pose>0 0 0 0 -0 0</pose>
          <geometry>
            <mesh>
              <scale>1 1 1</scale>
              <uri>https://fuel.ignitionrobotics.org/1.0/MovAi/models/pallet/tip/files/meshes/pallet.dae</uri>
            </mesh>
          </geometry>
        </visual>
        <visual name='boxes_visual'>
          <pose>-0.053875 0 0 0 -0 0</pose>
          <geometry>
            <mesh>
              <scale>1 1 1</scale>
              <uri>https://fuel.ignitionrobotics.org/1.0/movai/models/pallet_box_mobile/3/files/meshes/boxes.dae</uri>
            </mesh>
          </geometry>
        </visual>
      </link>
      <plugin name='ignition::gazebo::systems::PosePublisher' filename='ignition-gazebo-pose-publisher-system'>
        <publish_link_pose>1</publish_link_pose>
        <publish_collision_pose>0</publish_collision_pose>
        <publish_visual_pose>0</publish_visual_pose>
        <publish_nested_model_pose>1</publish_nested_model_pose>
        <update_frequency>20</update_frequency>
      </plugin>
      <static>1</static>
    </model>
    <model name='shelf_big_1'>
      <pose>13.9821 15.319 0 0 -0 0</pose>
      <self_collide>1</self_collide>
      <link name='shelf_big_base'>
        <pose>-0.5 0 0 0 -0 0</pose>
        <collision name='shelf_big_chassi_collision'>
          <pose>0 0 3 0 -0 0</pose>
          <geometry>
            <box>
              <size>2.1 18 6</size>
            </box>
          </geometry>
          <surface>
            <friction>
              <ode/>
            </friction>
            <bounce/>
            <contact/>
          </surface>
        </collision>
        <visual name='shelf_big_chassi_visual'>
          <pose>0 0 0 0 -0 1.5708</pose>
          <geometry>
            <mesh>
              <scale>1 1 1</scale>
              <uri>file:///home/truan/.ignition/fuel/fuel.ignitionrobotics.org/movai/models/shelf_big/2/meshes/shelf_big_movai.dae</uri>
            </mesh>
          </geometry>
        </visual>
      </link>
      <static>1</static>
    </model>
    <model name='shelf_big_2'>
      <pose>6.19777 -12.9647 0 0 -0 0</pose>
      <self_collide>1</self_collide>
      <link name='shelf_big_base'>
        <pose>-0.5 0 0 0 -0 0</pose>
        <collision name='shelf_big_chassi_collision'>
          <pose>0 0 3 0 -0 0</pose>
          <geometry>
            <box>
              <size>2.1 18 6</size>
            </box>
          </geometry>
          <surface>
            <friction>
              <ode/>
            </friction>
            <bounce/>
            <contact/>
          </surface>
        </collision>
        <visual name='shelf_big_chassi_visual'>
          <pose>0 0 0 0 -0 1.5708</pose>
          <geometry>
            <mesh>
              <scale>1 1 1</scale>
              <uri>file:///home/truan/.ignition/fuel/fuel.ignitionrobotics.org/movai/models/shelf_big/2/meshes/shelf_big_movai.dae</uri>
            </mesh>
          </geometry>
        </visual>
      </link>
      <static>1</static>
    </model>
    <model name='shelf_big_3'>
      <pose>0.594376 -12.9647 0 0 -0 0</pose>
      <self_collide>1</self_collide>
      <link name='shelf_big_base'>
        <pose>-0.5 0 0 0 -0 0</pose>
        <collision name='shelf_big_chassi_collision'>
          <pose>0 0 3 0 -0 0</pose>
          <geometry>
            <box>
              <size>2.1 18 6</size>
            </box>
          </geometry>
          <surface>
            <friction>
              <ode/>
            </friction>
            <bounce/>
            <contact/>
          </surface>
        </collision>
        <visual name='shelf_big_chassi_visual'>
          <pose>0 0 0 0 -0 1.5708</pose>
          <geometry>
            <mesh>
              <scale>1 1 1</scale>
              <uri>file:///home/truan/.ignition/fuel/fuel.ignitionrobotics.org/movai/models/shelf_big/2/meshes/shelf_big_movai.dae</uri>
            </mesh>
          </geometry>
        </visual>
      </link>
      <static>1</static>
    </model>
    <model name='shelf_big_4'>
      <pose>-5.36284 -12.9647 0 0 -0 0</pose>
      <self_collide>1</self_collide>
      <link name='shelf_big_base'>
        <pose>-0.5 0 0 0 -0 0</pose>
        <collision name='shelf_big_chassi_collision'>
          <pose>0 0 3 0 -0 0</pose>
          <geometry>
            <box>
              <size>2.1 18 6</size>
            </box>
          </geometry>
          <surface>
            <friction>
              <ode/>
            </friction>
            <bounce/>
            <contact/>
          </surface>
        </collision>
        <visual name='shelf_big_chassi_visual'>
          <pose>0 0 0 0 -0 1.5708</pose>
          <geometry>
            <mesh>
              <scale>1 1 1</scale>
              <uri>file:///home/truan/.ignition/fuel/fuel.ignitionrobotics.org/movai/models/shelf_big/2/meshes/shelf_big_movai.dae</uri>
            </mesh>
          </geometry>
        </visual>
      </link>
      <static>1</static>
    </model>
    <model name='shelf_7'>
      <pose>13.3818 -21.2416 0 0 -0 0</pose>
      <self_collide>1</self_collide>
      <link name='shelf_base'>
        <pose>-0.5 0 0 0 -0 0</pose>
        <collision name='shelf_chassi_collision'>
          <pose>0 0 0.9 0 -0 0</pose>
          <geometry>
            <box>
              <size>3.6 0.6 1.8</size>
            </box>
          </geometry>
          <surface>
            <friction>
              <ode/>
            </friction>
            <bounce/>
            <contact/>
          </surface>
        </collision>
        <visual name='shelf_chassi_visual'>
          <pose>0 0 0 0 -0 0</pose>
          <geometry>
            <mesh>
              <scale>0.2 0.3 0.3</scale>
              <uri>file:///home/truan/.ignition/fuel/fuel.ignitionrobotics.org/movai/models/shelf/1/meshes/shelf_big_movai.dae</uri>
            </mesh>
          </geometry>
        </visual>
      </link>
      <static>1</static>
    </model>
    <model name='shelf_8'>
      <pose>13.3818 -19.0028 0 0 -0 0</pose>
      <self_collide>1</self_collide>
      <link name='shelf_base'>
        <pose>-0.5 0 0 0 -0 0</pose>
        <collision name='shelf_chassi_collision'>
          <pose>0 0 0.9 0 -0 0</pose>
          <geometry>
            <box>
              <size>3.6 0.6 1.8</size>
            </box>
          </geometry>
          <surface>
            <friction>
              <ode/>
            </friction>
            <bounce/>
            <contact/>
          </surface>
        </collision>
        <visual name='shelf_chassi_visual'>
          <pose>0 0 0 0 -0 0</pose>
          <geometry>
            <mesh>
              <scale>0.2 0.3 0.3</scale>
              <uri>file:///home/truan/.ignition/fuel/fuel.ignitionrobotics.org/movai/models/shelf/1/meshes/shelf_big_movai.dae</uri>
            </mesh>
          </geometry>
        </visual>
      </link>
      <static>1</static>
    </model>
    <model name='shelf_9'>
      <pose>13.3818 -16.4478 0 0 -0 0</pose>
      <self_collide>1</self_collide>
      <link name='shelf_base'>
        <pose>-0.5 0 0 0 -0 0</pose>
        <collision name='shelf_chassi_collision'>
          <pose>0 0 0.9 0 -0 0</pose>
          <geometry>
            <box>
              <size>3.6 0.6 1.8</size>
            </box>
          </geometry>
          <surface>
            <friction>
              <ode/>
            </friction>
            <bounce/>
            <contact/>
          </surface>
        </collision>
        <visual name='shelf_chassi_visual'>
          <pose>0 0 0 0 -0 0</pose>
          <geometry>
            <mesh>
              <scale>0.2 0.3 0.3</scale>
              <uri>file:///home/truan/.ignition/fuel/fuel.ignitionrobotics.org/movai/models/shelf/1/meshes/shelf_big_movai.dae</uri>
            </mesh>
          </geometry>
        </visual>
      </link>
      <static>1</static>
    </model>
    <model name='shelf_10'>
      <pose>13.3818 -14.1028 0 0 -0 0</pose>
      <self_collide>1</self_collide>
      <link name='shelf_base'>
        <pose>-0.5 0 0 0 -0 0</pose>
        <collision name='shelf_chassi_collision'>
          <pose>0 0 0.9 0 -0 0</pose>
          <geometry>
            <box>
              <size>3.6 0.6 1.8</size>
            </box>
          </geometry>
          <surface>
            <friction>
              <ode/>
            </friction>
            <bounce/>
            <contact/>
          </surface>
        </collision>
        <visual name='shelf_chassi_visual'>
          <pose>0 0 0 0 -0 0</pose>
          <geometry>
            <mesh>
              <scale>0.2 0.3 0.3</scale>
              <uri>file:///home/truan/.ignition/fuel/fuel.ignitionrobotics.org/movai/models/shelf/1/meshes/shelf_big_movai.dae</uri>
            </mesh>
          </geometry>
        </visual>
      </link>
      <static>1</static>
    </model>
    <model name='pallet_box_0'>
      <pose>14.0222 -24.335 0.01 0 -0 0</pose>
      <self_collide>0</self_collide>
      <link name='pallet_base'>
        <pose>0 0 0 0 -0 0</pose>
        <inertial>
          <pose>0 0 0.4 0 -0 0</pose>
          <mass>200</mass>
          <inertia>
            <ixx>0.1</ixx>
            <ixy>0</ixy>
            <ixz>0</ixz>
            <iyy>0.1</iyy>
            <iyz>0</iyz>
            <izz>0.1</izz>
          </inertia>
        </inertial>
        <collision name='pallet_top_collision'>
          <pose>0 0 0.125 0 -0 0</pose>
          <geometry>
            <box>
              <size>1.22 0.8 0.04</size>
            </box>
          </geometry>
          <surface>
            <friction>
              <ode>
                <mu>0.4</mu>
                <mu2>0.4</mu2>
              </ode>
            </friction>
            <bounce/>
            <contact/>
          </surface>
        </collision>
        <collision name='pallet_center_collision'>
          <pose>0 0 0.055 0 -0 0</pose>
          <geometry>
            <box>
              <size>1.22 0.1 0.1</size>
            </box>
          </geometry>
          <surface>
            <friction>
              <ode/>
            </friction>
            <bounce/>
            <contact/>
          </surface>
        </collision>
        <collision name='pallet_left_collision'>
          <pose>0 -0.35 0.055 0 -0 0</pose>
          <geometry>
            <box>
              <size>1.22 0.1 0.1</size>
            </box>
          </geometry>
          <surface>
            <friction>
              <ode/>
            </friction>
            <bounce/>
            <contact/>
          </surface>
        </collision>
        <collision name='pallet_right_collision'>
          <pose>0 0.35 0.055 0 -0 0</pose>
          <geometry>
            <box>
              <size>1.22 0.1 0.1</size>
            </box>
          </geometry>
          <surface>
            <friction>
              <ode/>
            </friction>
            <bounce/>
            <contact/>
          </surface>
        </collision>
        <collision name='boxes_collision'>
          <pose>0 0 0.644 0 -0 0</pose>
          <geometry>
            <box>
              <size>1.22 0.8 1</size>
            </box>
          </geometry>
          <surface>
            <friction>
              <ode/>
            </friction>
            <bounce/>
            <contact/>
          </surface>
        </collision>
        <visual name='pallet_visual'>
          <pose>0 0 0 0 -0 0</pose>
          <geometry>
            <mesh>
              <scale>1 1 1</scale>
              <uri>https://fuel.ignitionrobotics.org/1.0/MovAi/models/pallet/tip/files/meshes/pallet.dae</uri>
            </mesh>
          </geometry>
        </visual>
        <visual name='boxes_visual'>
          <pose>-0.053875 0 0 0 -0 0</pose>
          <geometry>
            <mesh>
              <scale>1 1 1</scale>
              <uri>https://fuel.ignitionrobotics.org/1.0/movai/models/pallet_box_mobile/3/files/meshes/boxes.dae</uri>
            </mesh>
          </geometry>
        </visual>
      </link>
      <plugin name='ignition::gazebo::systems::PosePublisher' filename='ignition-gazebo-pose-publisher-system'>
        <publish_link_pose>1</publish_link_pose>
        <publish_collision_pose>0</publish_collision_pose>
        <publish_visual_pose>0</publish_visual_pose>
        <publish_nested_model_pose>1</publish_nested_model_pose>
        <update_frequency>20</update_frequency>
      </plugin>
      <static>1</static>
    </model>
  </world>
</sdf>
